Workbook

Sheet Báo cáo CV
A1: STT | B1: TÊN | C1: VỊ TRÍ | D1: Duyệt CV | E1: Kinh nghiệm BĐS | F1: CV ứng viên
A2: 1 | B2: Nguyễn Huỳnh Phúc | C2: Content Marketing
A3: 2 | B3: Hồ Nguyễn Khánh Hà | C3: Content Marketing
A4: 3 | B4: Đinh Cù Khánh Đăng | C4: Content Marketing
A5: 4 | B5: Nguyễn Hoàng Trúc Anh | C5: Content Marketing | D5: Đạt | E5: Chưa có | F5: Link topcv
A6: 5 | B6: Huỳnh Ngô Mỹ Tiên | C6: Content Marketing
A7: 6 | B7: Ngô Thị Hoài Thương | C7: Content Marketing
A8: 7 | B8: Lê Minh Quân | C8: Content Marketing | D8: Đạt | E8: Chưa có | F8: Link topcv
A9: 8 | B9: Dương Nguyễn Kim Mỹ | C9: Content Marketing | D9: Đạt | E9: Chưa có | F9: Link topcv
A10: 9 | B10: Lê Thị Như Quỳnh | C10: Content Marketing
A11: 10 | B11: Phạm Thị Nhi | C11: Content Marketing
A12: 11 | B12: Đinh Châu Trân | C12: Content Marketing
A13: 12 | B13: Trương Thanh Tuấn | C13: Content Marketing | D13: Đạt | E13: Đã có KN | F13: Link topcv
A14: 13 | B14: Hoàng Thị Thùy Linh | C14: Content Marketing | D14: Đạt | E14: Chưa có | F14: Link topcv
A15: 14 | B15: Đặng Ngọc Trúc Anh | C15: Content Marketing | D15: Đạt | E15: Chưa có | F15: Link topcv
A16: 15 | B16: Nguyễn Thị Ngọc Diệp | C16: Content Marketing

Sheet Theo dõi lượt đăng bài
A1: BÁO CÁO THEO DÕI LƯỢT ĐĂNG BÀI TRÊN CÁC ỨNG DỤNG TUYỂN DỤNG
A2: STT | B2: Kênh | C2: Nhóm | D2: Đường link nhóm/bài đăng | E2: Ngày đăng | F2: Ngày duyệt | G2: Trạng thái | H2: Hình
A3: 1 | B3: Facebook | C3: THỰC TẬP SINH NĂM 3,4 - INTERNSHIP CÓ LƯƠNG | D3: https://www.facebook.com/share/g/qLNDsM4NbLGidpa3/ | E3: 15:55 20/08/2024 | G3: Chờ duyệt | H3: Mẫu 1
A4: 2 | B4: TopCV | D4: https://www.topcv.vn/viec-lam/thuc-tap-sinh/1446013.html | E4: 16:32 20/08/2024 | F4: 14:20 21/08/2024
A5: 3 | B5: Facebook | C5: TUYỂN DỤNG THỰC TẬP SINH HCM | D5: https://www.facebook.com/share/g/S1fYS7MYry6Bz6b7/ | E5: 8:15 21/08/2024 | G5: Bị xóa (không tìm ra nguyên nhân)
A6: 4 | B6: Facebook | C6: Internships & Jobs in Vietnam | Thực tập & Việc làm | D6: https://www.facebook.com/share/g/vQUs3B2EXsKKUoKs/ | E6: 8:54 21/08/2024 | F6: 8:54 21/08/2026 | H6: Mẫu 2
A7: 5 | B7: Facebook | C7: TUYỂN DỤNG THỰC TẬP SINH CÓ LƯƠNG | D7: https://www.facebook.com/share/g/pX9uzZbUe5SiNch2/ | E7: 8:45 22/08/2024 | F7: 8:45 22/08/2027 | H7: Mẫu 3
A8: 6 | B8: Facebook | C8: THỰC TẬP CÓ LƯƠNG - PART TIME - INTERNSHIP | D8: https://www.facebook.com/share/g/QjX2MsgodqX66VWk/ | E8: 9:28 26/08/2024 | G8: Bị từ chối | H8: Mẫu 1
A9: 7 | B9: Facebook | C9: THỰC TẬP SINH NĂM 3,4 - INTERNSHIP CÓ LƯƠNG | D9: https://www.facebook.com/share/g/qLNDsM4NbLGidpa3/ | E9: 8:15 27/08/2024 | G9: Chờ duyệt | H9: Mẫu 2
A10: 8 | B10: Facebook | C10: Internships & Jobs in Vietnam | Thực tập & Việc làm | D10: https://www.facebook.com/share/g/vQUs3B2EXsKKUoKs/ | E10: 9:22 28/08/2024 | F10: 9:22 28/08/2024 | H10: Mẫu 3
A11: 9 | B11: Facebook | C11: TUYỂN DỤNG THỰC TẬP SINH CÓ LƯƠNG | D11: https://www.facebook.com/share/g/pX9uzZbUe5SiNch2/ | E11: 8:31 04/09/2024 | F11: 8:31 04/09/2024 | H11: Mẫu2
A12: 10 | B12: Facebook | C12: THỰC TẬP SINH - CƠ HỘI VIỆC LÀM - TP.HCM | D12: https://www.facebook.com/share/g/3b1wCrffDnhxWoPP/ | E12: 8:53 05/09/2024 | F12: 8:53 05/09/2024 | H12: Mẫu 2
A13: 11 | B13: Facebook | C13: THỰC TẬP SINH NĂM 3,4 - INTERNSHIP CÓ LƯƠNG | D13: https://www.facebook.com/share/g/qLNDsM4NbLGidpa3/ | E13: 9:07 06/09/2024 | G13: Chờ duyệt | H13: Mẫu 4
A14: 12 | B14: Facebook | C14: THỰC TẬP CÓ LƯƠNG - PART TIME - INTERNSHIP | D14: https://www.facebook.com/share/g/QjX2MsgodqX66VWk/ | E14: 9:20 09/09/2024 | G14: Chờ duyệt | H14: Mẫu 2
A15: 13 | B15: Facebook | C15: TUYỂN DỤNG THỰC TẬP SINH NĂM CUỐI | D15: https://www.facebook.com/share/g/HKFpGScsRBQqxjUN/ | E15: 8:33 11/09/2024 | F15: 8:33 11/09/2024 | H15: Mẫu 5
A16: 14 | B16: Facebook | C16: Internships & Jobs in Vietnam | Thực tập & Việc làm | D16: https://www.facebook.com/share/g/vQUs3B2EXsKKUoKs/ | E16: 8:37 12/09/2024 | F16: 8:37 12/09/2024 | H16: Mẫu 5
A17: 15 | B17: Facebook | C17: TUYỂN DỤNG THỰC TẬP SINH NĂM CUỐI | D17: https://www.facebook.com/share/g/HKFpGScsRBQqxjUN/ | E17: 9:12 17/09/2024 | F17: 9:12 17/09/2024 | H17: Mẫu 5
A18: 16 | B18: Facebook | C18: Tuyển Dụng - Việc Làm - Sài Gòn | D18: https://www.facebook.com/share/g/7mn7hXHwLk67KwGr/ | E18: 8:11 18/09/2024 | F18: 8:11 18/09/2024 | H18: Mẫu 2
A19: 17 | B19: Facebook | C19: Tuyển Dụng - Tìm Việc Làm TP.HCM | D19: https://www.facebook.com/share/g/R1DLwHMF9WbPLhuy/ | E19: 8:35 19/09/2024 | F19: 8:35 19/09/2024 | H19: Mẫu 5
A20: 18 | B20: Facebook | C20: Thực Tập Sinh - Internship Có Lương - Việc Làm Mới Tốt Nghiệp | D20: https://www.facebook.com/share/g/2bRQmJLZootrh72L/ | E20: 08:38 24/09/2024 | F20: 08:38 24/09/2024 | H20: Mẫu 3
A21: 19 | B21: Facebook | C21: Tuyển Dụng Việc Làm TPHCM - Tìm Việc Làm TPHCM | D21: https://www.facebook.com/share/g/unqzbpGwif9bSheK/ | E21: 8:24 25/09/2024 | F21: 8:24 25/09/2024 | H21: Mẫu 4
A22: 20 | B22: Facebook | C22: TUYỂN DỤNG THỰC TẬP SINH NĂM CUỐI | D22: https://www.facebook.com/share/g/HKFpGScsRBQqxjUN/ | E22: 9:00 26/09/2024 | F22: 9:00 26/09/2024 | H22: Mẫu 8
A23: 21 | B23: Facebook | C23: THỰC TẬP DOANH NGHIỆP (CÓ LƯƠNG / DẤU MỘC) - SINH VIÊN NĂM CUỐI | D23: https://www.facebook.com/share/g/H7eMJV4iuxZaMShi/ | E23: 9:23 30/9/2024 | G23: Chờ duyệt | H23: Mẫu 4
A24: 22 | B24: Facebook | C24: THỰC TẬP CÓ LƯƠNG - PART TIME - INTERNSHIP | D24: https://www.facebook.com/share/g/euvbCh7TZAx5b5qm/ | E24: 9:59 01/10/2024 | G24: Chờ duyệt | H24: Mẫu 2
A25: 23 | B25: Facebook | C25: Thực Tập Sinh - Internship Có Lương - Việc Làm Mới Tốt Nghiệp | D25: https://www.facebook.com/share/g/2bRQmJLZootrh72L/ | E25: 9:19 02/10/2024 | F25: 9:19 02/10/2024 | H25: Mẫu7
A26: 24 | B26: Facebook | C26: Tuyển dụng sinh viên thực tập năm cuối | D26: https://www.facebook.com/share/g/4rjXQXqjFzAhqkVJ/ | E26: 8:29 03/10/2024 | F26: 8:29 03/10/2024
A27: 25 | B27: Facebook | C27: Thực Tập Sinh - Cơ Hội Việc Làm | D27: https://www.facebook.com/share/g/8XMKUV26bTNcscFJ/ | E27: 11:00 11/10/2024 | F27: 11:00 11/10/2024 | H27: Mẫu 2
A28: 26 | B28: Facebook | C28: JOB - THỰC TẬP SINH NHÂN SỰ (Miền Nam) | D28: https://www.facebook.com/share/g/Khj6R8mt66tMcC1j/ | E28: 10:12 14/10/2024 | G28: Chờ duyệt | H28: Mẫu 11
A29: 27 | B29: Facebook | C29: Tuyển Dụng Sinh Siên Thực Tập Năm Cuối | D29: https://www.facebook.com/share/g/QHq7Stpst9YS5v6r/ | E29: 13:14 15/10/2024 | F29: 13:14 15/10/2025 | H29: Mẫu 13
A30: 28 | B30: Facebook | C30: TUYỂN DỤNG SINH VIÊN THỰC TẬP NĂM CUỐI | D30: https://www.facebook.com/share/g/HKFpGScsRBQqxjUN/ | E30: 8:43 16/10/2024 | F30: 8:43 16/10/2024 | H30: Mẫu 9
A31: 29 | B31: Facebook | C31: VIỆC LÀM THỰC TẬP SINH - SINH VIÊN MỚI TỐT NGHIỆP | D31: https://www.facebook.com/share/g/GdctKfBhZHuDUbWe/ | E31: 8:45 22/10/2024 | F31: 8:45 22/10/2024 | H31: Mẫu 13
A32: 30 | B32: Facebook | C32: Tuyển dụng sinh viên thực tập năm cuối | D32: https://www.facebook.com/share/g/4tfHNkWwdPmHYNif/ | E32: 8:24 23/10/2024 | F32: 8:24 23/10/2024 | H32: Mẫu 18
A33: 31 | B33: Facebook | C33: THỰC TẬP CÓ LƯƠNG - PART TIME - INTERNSHIP | D33: https://www.facebook.com/share/g/euvbCh7TZAx5b5qm/ | E33: 8:19 24/10/2024 | G33: Chờ duyệt | H33: Mẫu 13
A34: 32 | B34: Facebook | C34: TUYỂN DỤNG SINH VIÊN THỰC TẬP NĂM CUỐI | D34: https://www.facebook.com/share/g/15AsTEiWNt/ | E34: 13:47 12/11/2024 | F34: 13:47 12/11/2024 | H34: Mẫu 16
A35: 33 | B35: Facebook | C35: TUYỂN DỤNG THỰC TẬP SINH CÓ LƯƠNG | D35: https://www.facebook.com/share/g/1DSD6GyUiP/ | E35: 8:42 19/11/2024 | F35: 8:42 19/11/2024 | H35: Mẫu 16
A36: 34 | B36: Facebook | C36: TUYỂN DỤNG SINH VIÊN MỚI RA TRƯỜNG, THỰC TẬP SINH | D36: https://www.facebook.com/share/g/15fMKje3kG/ | E36: 8:27 20/11/2024 | F36: 8:27 20/11/2024 | H36: Mẫu 18
A37: 35 | B37: Facebook | C37: Tuyển dụng sinh viên thực tập năm cuối | D37: https://www.facebook.com/share/g/18MPQTfLpp/ | E37: 8:23 21/11/2024 | F37: 8:23 21/11/2024 | H37: Mẫu 15
A38: 11 | B38: Facebook | C38: THỰC TẬP SINH NĂM 3, 4 - INTERNSHIP CÓ LƯƠNG | D38: https://www.facebook.com/share/g/1Df3GkvsZv/ | E38: 8:16 22/11/2024 | G38: Chờ duyệt | H38: Mẫu 4
A39: 36 | B39: Facebook | C39: Jobs & Internship in Ho Chi Minh City | D39: https://www.facebook.com/share/g/1WcVrwExLM/ | E39: 9:08 27/11/2024 | G39: Chờ duyệt | H39: Mẫu 10
A40: 37 | B40: Facebook | C40: THỰC TẬP SINH - CƠ HỘI VIỆC LÀM - TP.HCM | D40: https://www.facebook.com/share/g/17d5VaMiG9/ | E40: 10:56 28/11/2024 | F40: 10:56 28/11/2024 | H40: Mẫu 16
...

Sheet Tuần
A2: MẪU BÁO CÁO TUYỂN DỤNG TTS KD THEO THỜI GIAN TỪ 19/8/2024 ĐẾN 04/01/2025
A4: Nguồn | B4: Số hồ sơ nhận được | C4: Số hồ sơ đạt yêu cầu | D4: Số lượng tham gia PV | E4: Số lượng đạt PV | F4: Số lượng nhận việc | G4: Số lượng làm chính thức
A5: Tuần 1: Từ 19/8 đến 24/8
A6: TopCV | B6: 6 | C6: 4 | D6: 2 | E6: 2 | F6: 0 | G6: 0
A7: Facebook | B7: 0 | C7: 0 | D7: 0 | E7: 0 | F7: 0 | G7: 0
A8: Tổng số | B8: =SUM(B6:B7) -> 6 | C8: =SUM(C5:C7) -> 4 | D8: =SUM(D6:D7) -> 2 | E8: =SUM(E5:E7) -> 2 | F8: 0 | G8: 0
A9: Tuần 2: Từ 26/8 đến 31/8
A10: TopCV | B10: =sum('T82024 BC ngày'!B18,'T82024 BC ngày'!B22,'T82024 BC ngày'!B26) -> 11 | C10: =sum('T82024 BC ngày'!C18,'T82024 BC ngày'!C22,'T82024 BC ngày'!C26) -> 9 | D10: =sum('T82024 BC ngày'!D18,'T82024 BC ngày'!D22,'T82024 BC ngày'!D26) -> 5 | E10: =sum('T82024 BC ngày'!E18,'T82024 BC ngày'!E22,'T82024 BC ngày'!E26) -> 5 | F10: 3 | G10: 0
A11: Facebook | B11: 1 | C11: 1 | D11: 0 | E11: 0 | F11: 0 | G11: 0
A12: Tổng số | B12: =SUM(B10:B11) -> 12 | C12: =SUM(C9:C11) -> 10 | D12: =SUM(D10:D11) -> 5 | E12: =SUM(E9:E11) -> 5 | F12: =SUM(F10:F11) -> 3 | G12: 0
A13: Tuần 3: Từ 02/9 đến 07/9
A14: TopCV | B14: =SUM('T92024 BC ngày'!B6,'T92024 BC ngày'!B10,'T92024 BC ngày'!B14) -> 16 | C14: =SUM('T92024 BC ngày'!C6,'T92024 BC ngày'!C10,'T92024 BC ngày'!C14,) -> 12 | D14: =SUM('T92024 BC ngày'!D6,'T92024 BC ngày'!D10,'T92024 BC ngày'!D14,) -> 4 | E14: =SUM('T92024 BC ngày'!E6,'T92024 BC ngày'!E10,'T92024 BC ngày'!E14) -> 3 | F14: =SUM('T92024 BC ngày'!F6,'T92024 BC ngày'!F10,'T92024 BC ngày'!F14,) -> 4 | G14: =SUM('T92024 BC ngày'!G6,'T92024 BC ngày'!G10,'T92024 BC ngày'!G14) -> 3
A15: Facebook | B15: 0 | C15: 0 | D15: 0 | E15: 0 | F15: 0 | G15: =SUM('T92024 BC ngày'!G7,'T92024 BC ngày'!G11,'T92024 BC ngày'!G15) -> 0
A16: Tổng số | B16: 0 | C16: =SUM(C13:C15) -> 12 | D16: 0 | E16: =SUM(E13:E15) -> 3 | F16: =SUM(F14:F15) -> 4 | G16: =SUM(G14:G15) -> 3
A17: Tuần 4: Từ 09/9 đến 14/9
A18: TopCV | B18: =SUM('T92024 BC ngày'!B18,'T92024 BC ngày'!B22,'T92024 BC ngày'!B26) -> 18 | C18: =SUM('T92024 BC ngày'!C18,'T92024 BC ngày'!C22,'T92024 BC ngày'!C26) -> 15 | D18: =SUM('T92024 BC ngày'!D18,'T92024 BC ngày'!D22,'T92024 BC ngày'!D26) -> 3 | E18: =SUM('T92024 BC ngày'!E18,'T92024 BC ngày'!E22,'T92024 BC ngày'!E26) -> 3 | F18: =SUM('T92024 BC ngày'!F18,'T92024 BC ngày'!F22,'T92024 BC ngày'!F26) -> 4 | G18: =SUM('T92024 BC ngày'!G18,'T92024 BC ngày'!G22,'T92024 BC ngày'!G26) -> 4
A19: Facebook | B19: =SUM('T92024 BC ngày'!B19,'T92024 BC ngày'!B23,'T92024 BC ngày'!B27) -> 5 | C19: =SUM('T92024 BC ngày'!C19,'T92024 BC ngày'!C23,'T92024 BC ngày'!C27) -> 5 | D19: =SUM('T92024 BC ngày'!D19,'T92024 BC ngày'!D23,'T92024 BC ngày'!D27) -> 0 | E19: =SUM('T92024 BC ngày'!E19,'T92024 BC ngày'!E23,'T92024 BC ngày'!E27) -> 0 | F19: =SUM('T92024 BC ngày'!F19,'T92024 BC ngày'!F23,'T92024 BC ngày'!F27) -> 0 | G19: =SUM('T92024 BC ngày'!G19,'T92024 BC ngày'!G23,'T92024 BC ngày'!G27) -> 0
A20: Tổng số | B20: =SUM(B18:B19) -> 23 | C20: =SUM(C17:C19) -> 20 | D20: =SUM(D18:D19) -> 3 | E20: =SUM(E18:E19) -> 3 | F20: =SUM(F18:F19) -> 4 | G20: =SUM(G18:G19) -> 4
A21: Tuần 5: Từ 16/9 đến 21/9
A22: TopCV | B22: ='T92024 BC ngày'!B30+'T92024 BC ngày'!B34+'T92024 BC ngày'!B38 -> 22 | C22: ='T92024 BC ngày'!C30+'T92024 BC ngày'!C34+'T92024 BC ngày'!C38 -> 16 | D22: ='T92024 BC ngày'!D30+'T92024 BC ngày'!D34+'T92024 BC ngày'!D38 -> 6 | E22: ='T92024 BC ngày'!E30+'T92024 BC ngày'!E34+'T92024 BC ngày'!E38 -> 5 | F22: ='T92024 BC ngày'!F30+'T92024 BC ngày'!F34+'T92024 BC ngày'!F38 -> 3 | G22: ='T92024 BC ngày'!G30+'T92024 BC ngày'!G34+'T92024 BC ngày'!G38 -> 3
A23: Facebook | B23: ='T92024 BC ngày'!B31+'T92024 BC ngày'!B35+'T92024 BC ngày'!B39 -> 0 | C23: ='T92024 BC ngày'!C31+'T92024 BC ngày'!C35+'T92024 BC ngày'!C39 -> 0 | D23: ='T92024 BC ngày'!D31+'T92024 BC ngày'!D35+'T92024 BC ngày'!D39 -> 0 | E23: ='T92024 BC ngày'!E31+'T92024 BC ngày'!E35+'T92024 BC ngày'!E39 -> 0 | F23: ='T92024 BC ngày'!F31+'T92024 BC ngày'!F35+'T92024 BC ngày'!F39 -> 0 | G23: ='T92024 BC ngày'!G31+'T92024 BC ngày'!G35+'T92024 BC ngày'!G39 -> 0
A24: Tổng số | B24: ='T92024 BC ngày'!B32+'T92024 BC ngày'!B36+'T92024 BC ngày'!B40 -> 22 | C24: ='T92024 BC ngày'!C32+'T92024 BC ngày'!C36+'T92024 BC ngày'!C40 -> 16 | D24: ='T92024 BC ngày'!D32+'T92024 BC ngày'!D36+'T92024 BC ngày'!D40 -> 6 | E24: ='T92024 BC ngày'!E32+'T92024 BC ngày'!E36+'T92024 BC ngày'!E40 -> 5 | F24: ='T92024 BC ngày'!F32+'T92024 BC ngày'!F36+'T92024 BC ngày'!F40 -> 3 | G24: ='T92024 BC ngày'!G32+'T92024 BC ngày'!G36+'T92024 BC ngày'!G40 -> 3
A25: Tuần 6: Từ 23/9 đến 28/9
A26: TopCV | B26: =SUM('T92024 BC ngày'!B42,'T92024 BC ngày'!B46,'T92024 BC ngày'!B50) -> 9 | C26: =SUM('T92024 BC ngày'!C42,'T92024 BC ngày'!C46,'T92024 BC ngày'!C50) -> 7 | D26: =SUM('T92024 BC ngày'!D42,'T92024 BC ngày'!D46,'T92024 BC ngày'!D50) -> 5 | E26: =SUM('T92024 BC ngày'!E42,'T92024 BC ngày'!E46,'T92024 BC ngày'!E50) -> 4 | F26: =SUM('T92024 BC ngày'!F42,'T92024 BC ngày'!F46,'T92024 BC ngày'!F50) -> 3 | G26: =SUM('T92024 BC ngày'!G42,'T92024 BC ngày'!G46,'T92024 BC ngày'!G50) -> 3
A27: Facebook | B27: =SUM('T92024 BC ngày'!B43,'T92024 BC ngày'!B47,'T92024 BC ngày'!B51) -> 7 | C27: =SUM('T92024 BC ngày'!C43,'T92024 BC ngày'!C47,'T92024 BC ngày'!C51) -> 6 | D27: =SUM('T92024 BC ngày'!D43,'T92024 BC ngày'!D47,'T92024 BC ngày'!D51) -> 0 | E27: =SUM('T92024 BC ngày'!E43,'T92024 BC ngày'!E47,'T92024 BC ngày'!E51) -> 0 | F27: =SUM('T92024 BC ngày'!F43,'T92024 BC ngày'!F47,'T92024 BC ngày'!F51) -> 0 | G27: =SUM('T92024 BC ngày'!G43,'T92024 BC ngày'!G47,'T92024 BC ngày'!G51) -> 0
A28: Tổng số | B28: =SUM('T92024 BC ngày'!B44,'T92024 BC ngày'!B48,'T92024 BC ngày'!B52) -> 16 | C28: =SUM('T92024 BC ngày'!C44,'T92024 BC ngày'!C48,'T92024 BC ngày'!C52) -> 13 | D28: =SUM('T92024 BC ngày'!D44,'T92024 BC ngày'!D48,'T92024 BC ngày'!D52) -> 5 | E28: =SUM('T92024 BC ngày'!E44,'T92024 BC ngày'!E48,'T92024 BC ngày'!E52) -> 4 | F28: =SUM('T92024 BC ngày'!F44,'T92024 BC ngày'!F48,'T92024 BC ngày'!F52) -> 3 | G28: =SUM('T92024 BC ngày'!G44,'T92024 BC ngày'!G48,'T92024 BC ngày'!G52) -> 3
A29: Tuần 7: Từ 30/9 đến 05/10
A30: TopCV | B30: =SUM('T102024 BC ngày'!B6,'T102024 BC ngày'!B10,'T102024 BC ngày'!B14,'T102024 BC ngày'!B18) -> 15 | C30: =SUM('T102024 BC ngày'!C6,'T102024 BC ngày'!C10,'T102024 BC ngày'!C14,'T102024 BC ngày'!C18) -> 13 | D30: =SUM('T102024 BC ngày'!D6,'T102024 BC ngày'!D10,'T102024 BC ngày'!D14,'T102024 BC ngày'!D18) -> 1 | E30: =SUM('T102024 BC ngày'!E6,'T102024 BC ngày'!E10,'T102024 BC ngày'!E14,'T102024 BC ngày'!E18) -> 0 | F30: =SUM('T102024 BC ngày'!F6,'T102024 BC ngày'!F10,'T102024 BC ngày'!F14,'T102024 BC ngày'!F18) -> 3 | G30: =SUM('T102024 BC ngày'!G6,'T102024 BC ngày'!G10,'T102024 BC ngày'!G14,'T102024 BC ngày'!G18) -> 2
A31: Facebook | B31: =SUM('T102024 BC ngày'!B7,'T102024 BC ngày'!B11,'T102024 BC ngày'!B15,'T102024 BC ngày'!B19) -> 1 | C31: =SUM('T102024 BC ngày'!C7,'T102024 BC ngày'!C11,'T102024 BC ngày'!C15,'T102024 BC ngày'!C19) -> 1 | D31: =SUM('T102024 BC ngày'!D7,'T102024 BC ngày'!D11,'T102024 BC ngày'!D15,'T102024 BC ngày'!D19) -> 0 | E31: =SUM('T102024 BC ngày'!E7,'T102024 BC ngày'!E11,'T102024 BC ngày'!E15,'T102024 BC ngày'!E19) -> 0 | F31: =SUM('T102024 BC ngày'!F7,'T102024 BC ngày'!F11,'T102024 BC ngày'!F15,'T102024 BC ngày'!F19) -> 0 | G31: =SUM('T102024 BC ngày'!G7,'T102024 BC ngày'!G11,'T102024 BC ngày'!G15,'T102024 BC ngày'!G19) -> 0
A32: Tổng số | B32: =SUM(B30:B31) -> 16 | C32: =SUM(C30:C31) -> 14 | D32: =SUM(D30:D31) -> 1 | E32: =SUM(E30:E31) -> 0 | F32: =SUM(F30:F31) -> 3 | G32: =SUM(G30:G31) -> 2
A33: Tuần 8: Từ 07/10 đến 12/10
A34: TopCV | B34: =SUM('T102024 BC ngày'!B22,'T102024 BC ngày'!B26) -> 19 | C34: =SUM('T102024 BC ngày'!C22,'T102024 BC ngày'!C26) -> 8 | D34: =SUM('T102024 BC ngày'!D22,'T102024 BC ngày'!D26) -> 0 | E34: =SUM('T102024 BC ngày'!E22,'T102024 BC ngày'!E26) -> 0 | F34: =SUM('T102024 BC ngày'!F22,'T102024 BC ngày'!F26) -> 2 | G34: =SUM('T102024 BC ngày'!G22,'T102024 BC ngày'!G26) -> 3
A35: Facebook | B35: =SUM('T102024 BC ngày'!B23,'T102024 BC ngày'!B27) -> 1 | C35: =SUM('T102024 BC ngày'!C23,'T102024 BC ngày'!C27) -> 1 | D35: =SUM('T102024 BC ngày'!D23,'T102024 BC ngày'!D27) -> 0 | E35: =SUM('T102024 BC ngày'!E23,'T102024 BC ngày'!E27) -> 0 | F35: =SUM('T102024 BC ngày'!F23,'T102024 BC ngày'!F27) -> 0 | G35: =SUM('T102024 BC ngày'!G23,'T102024 BC ngày'!G27) -> 0
A36: Tổng số | B36: =SUM(B34:B35) -> 20 | C36: =SUM(C34:C35) -> 9 | D36: =SUM(D34:D35) -> 0 | E36: =SUM(E34:E35) -> 0 | F36: =SUM(F34:F35) -> 2 | G36: =SUM(G34:G35) -> 3
A37: Tuần 9: Từ 14/10 đến 19/10
A38: TopCV | B38: =SUM('T102024 BC ngày'!B30,'T102024 BC ngày'!B34,'T102024 BC ngày'!B38) -> 14 | C38: =SUM('T102024 BC ngày'!C30,'T102024 BC ngày'!C34,'T102024 BC ngày'!C38) -> 6 | D38: =SUM('T102024 BC ngày'!D30,'T102024 BC ngày'!D34,'T102024 BC ngày'!D38) -> 0 | E38: =SUM('T102024 BC ngày'!E30,'T102024 BC ngày'!E34,'T102024 BC ngày'!E38) -> 0 | F38: =SUM('T102024 BC ngày'!F30,'T102024 BC ngày'!F34,'T102024 BC ngày'!F38) -> 0 | G38: =SUM('T102024 BC ngày'!G30,'T102024 BC ngày'!G34,'T102024 BC ngày'!G38) -> 1
A39: Facebook | B39: =SUM('T102024 BC ngày'!B31,'T102024 BC ngày'!B35,'T102024 BC ngày'!B39) -> 0 | C39: =SUM('T102024 BC ngày'!C31,'T102024 BC ngày'!C35,'T102024 BC ngày'!C39) -> 0 | D39: =SUM('T102024 BC ngày'!D31,'T102024 BC ngày'!D35,'T102024 BC ngày'!D39) -> 0 | E39: =SUM('T102024 BC ngày'!E31,'T102024 BC ngày'!E35,'T102024 BC ngày'!E39) -> 0 | F39: =SUM('T102024 BC ngày'!F31,'T102024 BC ngày'!F35,'T102024 BC ngày'!F39) -> 0 | G39: =SUM('T102024 BC ngày'!G31,'T102024 BC ngày'!G35,'T102024 BC ngày'!G39) -> 0
A40: Tổng số | B40: =SUM(B38:B39) -> 14 | C40: =SUM(C38:C39) -> 6 | D40: =SUM(D38:D39) -> 0 | E40: =SUM(E38:E39) -> 0 | F40: =SUM(F38:F39) -> 0 | G40: =SUM(G38:G39) -> 1
A41: Tuần 10: Từ 21/10 đến 26/10
A42: TopCV | B42: =SUM('T102024 BC ngày'!B42,'T102024 BC ngày'!B46,'T102024 BC ngày'!B50) -> 8 | C42: =SUM('T102024 BC ngày'!C42,'T102024 BC ngày'!C46,'T102024 BC ngày'!C50) -> 6 | D42: =SUM('T102024 BC ngày'!D42,'T102024 BC ngày'!D46,'T102024 BC ngày'!D50) -> 0 | E42: =SUM('T102024 BC ngày'!E42,'T102024 BC ngày'!E46,'T102024 BC ngày'!E50) -> 0 | F42: =SUM('T102024 BC ngày'!F42,'T102024 BC ngày'!F46,'T102024 BC ngày'!F50) -> 0 | G42: =SUM('T102024 BC ngày'!G42,'T102024 BC ngày'!G46,'T102024 BC ngày'!G50) -> 0
...

Sheet T102024 BC ngày
A2: MẪU BÁO CÁO TUYỂN DỤNG TTS KD THEO THỜI GIAN THÁNG 10/2024
A4: Nguồn | B4: Số hồ sơ nhận được | C4: Số hồ sơ đạt yêu cầu | D4: Số lượng tham gia PV | E4: Số lượng đạt PV | F4: Số lượng nhận việc | G4: Số lượng làm chính thức
A5: 45565
A6: TopCV | B6: 6 | C6: 4 | D6: 0 | E6: 0 | F6: 0 | G6: 0
A7: Facebook | B7: 0 | C7: 0 | D7: 0 | E7: 0 | F7: 0 | G7: 0
A8: Tổng số | B8: =SUM(B6:B7) -> 6 | C8: =SUM(C6:C7) -> 4 | D8: =SUM(D6:D7) -> 0 | E8: =SUM(E6:E7) -> 0 | F8: =SUM(F6:F7) -> 0 | G8: =SUM(G6:G7) -> 0
A9: 45566
A10: TopCV | B10: 5 | C10: 5 | D10: 0 | E10: 0 | F10: 0 | G10: 0
A11: Facebook | B11: 0 | C11: 0 | D11: 0 | E11: 0 | F11: 0 | G11: 0
A12: Tổng số | B12: =SUM(B10:B11) -> 5 | C12: =SUM(C10:C11) -> 5 | D12: =SUM(D10:D11) -> 0 | E12: =SUM(E10:E11) -> 0 | F12: =SUM(F10:F11) -> 0 | G12: =SUM(G10:G11) -> 0
A13: 45567
A14: TopCV | B14: 3 | C14: 3 | D14: 0 | E14: 0 | F14: 3 | G14: 2
A15: Facebook | B15: 0 | C15: 0 | D15: 0 | E15: 0 | F15: 0 | G15: 0
A16: Tổng số | B16: =SUM(B14:B15) -> 3 | C16: =SUM(C14:C15) -> 3 | D16: =SUM(D14:D15) -> 0 | E16: =SUM(E14:E15) -> 0 | F16: =SUM(F14:F15) -> 3 | G16: =SUM(G14:G15) -> 2
A17: 45568
A18: TopCV | B18: 1 | C18: 1 | D18: 1 | E18: 0 | F18: 0 | G18: 0
A19: Facebook | B19: 1 | C19: 1 | D19: 0 | E19: 0 | F19: 0 | G19: 0
A20: Tổng số | B20: =SUM(B18:B19) -> 2 | C20: =SUM(C18:C19) -> 2 | D20: =SUM(D18:D19) -> 1 | E20: =SUM(E18:E19) -> 0 | F20: =SUM(F18:F19) -> 0 | G20: =SUM(G18:G19) -> 0
A21: 45575
A22: TopCV | B22: 1 | C22: 0 | D22: 0 | E22: 0 | F22: 2 | G22: 3
A23: Facebook | B23: 0 | C23: 0 | D23: 0 | E23: 0 | F23: 0 | G23: 0
A24: Tổng số | B24: =SUM(B22:B23) -> 1 | C24: =SUM(C22:C23) -> 0 | D24: =SUM(D22:D23) -> 0 | E24: =SUM(E22:E23) -> 0 | F24: =SUM(F22:F23) -> 2 | G24: =SUM(G22:G23) -> 3
A25: 45576
A26: TopCV | B26: 18 | C26: 8 | D26: 0 | E26: 0 | F26: 0 | G26: 0
A27: Facebook | B27: 1 | C27: 1 | D27: 0 | E27: 0 | F27: 0 | G27: 0
A28: Tổng số | B28: =SUM(B26:B27) -> 19 | C28: =SUM(C26:C27) -> 9 | D28: =SUM(D26:D27) -> 0 | E28: =SUM(E26:E27) -> 0 | F28: =SUM(F26:F27) -> 0 | G28: =SUM(G26:G27) -> 0
A29: 45579
A30: TopCV | B30: 12 | C30: 6 | D30: 0 | E30: 0 | F30: 0 | G30: 0
A31: Facebook | B31: 0 | C31: 0 | D31: 0 | E31: 0 | F31: 0 | G31: 0
A32: Tổng số | B32: =SUM(B30:B31) -> 12 | C32: =SUM(C30:C31) -> 6 | D32: =SUM(D30:D31) -> 0 | E32: =SUM(E30:E31) -> 0 | F32: =SUM(F30:F31) -> 0 | G32: =SUM(G30:G31) -> 0
A33: 45580
A34: TopCV | B34: 1 | C34: 0 | D34: 0 | E34: 0 | F34: 0 | G34: 1
A35: Facebook | B35: 0 | C35: 0 | D35: 0 | E35: 0 | F35: 0 | G35: 0
A36: Tổng số | B36: =SUM(B34:B35) -> 1 | C36: =SUM(C34:C35) -> 0 | D36: =SUM(D34:D35) -> 0 | E36: =SUM(E34:E35) -> 0 | F36: =SUM(F34:F35) -> 0 | G36: =SUM(G34:G35) -> 1
A37: 45581
A38: TopCV | B38: 1 | C38: 0 | D38: 0 | E38: 0 | F38: 0 | G38: 0
A39: Facebook | B39: 0 | C39: 0 | D39: 0 | E39: 0 | F39: 0 | G39: 0
A40: Tổng số | B40: 0 | C40: =SUM(C37:C39) -> 0 | D40: 0 | E40: =SUM(E37:E39) -> 0 | F40: 0 | G40: 0
A41: 45587
A42: TopCV | B42: 6 | C42: 4 | D42: 0 | E42: 0 | F42: 0 | G42: 0
...

Sheet T82024 BC ngày
A2: MẪU BÁO CÁO TUYỂN DỤNG TTS KD THEO THỜI GIAN THÁNG 8/2024
A4: Nguồn | B4: Số hồ sơ nhận được | C4: Số hồ sơ đạt yêu cầu | D4: Số lượng tham gia PV | E4: Số lượng đạt PV | F4: Số lượng nhận việc | G4: Số lượng làm chính thức
A5: 45524
A6: TopCV | B6: 0 | C6: 0 | D6: 0 | E6: 0 | F6: 0 | G6: 0
A7: Facebook | B7: 1 | C7: 1 | D7: 0 | E7: 0 | F7: 0 | G7: 0
A8: Tổng số | B8: =SUM(B6:B7) -> 1 | C8: =SUM(C5:C7) -> 1 | D8: 0 | E8: =SUM(E5:E7) -> 0 | F8: 0 | G8: 0
A9: 45525
A10: TopCV | B10: 3 | C10: 3 | D10: 0 | E10: 0 | F10: 0 | G10: 0
A11: Facebook | B11: 0 | C11: 0 | D11: 0 | E11: 0 | F11: 0 | G11: 0
A12: Tổng số | B12: =SUM(B10:B11) -> 3 | C12: =SUM(C9:C11) -> 3 | D12: 0 | E12: =SUM(E9:E11) -> 0 | F12: 0 | G12: 0
A13: 45526
A14: TopCV | B14: 2 | C14: 0 | D14: 2 | E14: 2 | F14: 0 | G14: 0
A15: Facebook | B15: 0 | C15: 0 | D15: 0 | E15: 0 | F15: 0 | G15: 0
A16: Tổng số | B16: =SUM(B14:B15) -> 2 | C16: =SUM(C13:C15) -> 0 | D16: =SUM(D14:D15) -> 2 | E16: =SUM(E13:E15) -> 2 | F16: 0 | G16: 0
A17: 45530
A18: TopCV | B18: 4 | C18: 3 | D18: 1 | E18: 1 | F18: 0 | G18: 0
A19: Facebook | B19: 0 | C19: 0 | D19: 0 | E19: 0 | F19: 0 | G19: 0
A20: Tổng số | B20: =SUM(B18:B19) -> 4 | C20: =SUM(C17:C19) -> 3 | D20: =SUM(D18:D19) -> 1 | E20: =SUM(E17:E19) -> 1 | F20: 0 | G20: 0
A21: 45531
A22: TopCV | B22: 3 | C22: 2 | D22: 1 | E22: 1 | F22: 0 | G22: 0
A23: Facebook | B23: 0 | C23: 0 | D23: 0 | E23: 0 | F23: 0 | G23: 0
A24: Tổng số | B24: =SUM(B22:B23) -> 3 | C24: =SUM(C21:C23) -> 2 | D24: =SUM(D22:D23) -> 1 | E24: =SUM(E21:E23) -> 1 | F24: 0 | G24: 0
A25: 45532
A26: TopCV | B26: 4 | C26: 4 | D26: 3 | E26: 3 | F26: 3 | G26: 0
A27: Facebook | B27: 1 | C27: 1 | D27: 0 | E27: 0 | F27: 0 | G27: 0
A28: Tổng số | B28: =SUM(B26:B27) -> 5 | C28: =SUM(C25:C27) -> 5 | D28: =SUM(D26:D27) -> 3 | E28: =SUM(E25:E27) -> 3 | F28: =SUM(F26:F27) -> 3 | G28: 0
A29: Tổng tháng | B29: =SUM(B8,B12,B16,B20,B24,B28) -> 18 | C29: =SUM(C8,C12,C16,C20,C24,C28) -> 14 | D29: =SUM(D8,D12,D16,D20,D24,D28) -> 7 | E29: =SUM(E8,E12,E16,E20,E24,E28) -> 7 | F29: =SUM(F8,F12,F16,F20,F24,F28) -> 3 | G29: =SUM(G8,G12,G16,G20,G24,G28) -> 0

Sheet T92024 BC ngày
A2: MẪU BÁO CÁO TUYỂN DỤNG TTS KD THEO THỜI GIAN THÁNG 9/2024
A4: Nguồn | B4: Số hồ sơ nhận được | C4: Số hồ sơ đạt yêu cầu | D4: Số lượng tham gia PV | E4: Số lượng đạt PV | F4: Số lượng nhận việc | G4: Số lượng làm chính thức
A5: 45539
A6: TopCV | B6: 13 | C6: 9 | D6: 1 | E6: 0 | F6: 4 | G6: 3
A7: Facebook | B7: 0 | C7: 0 | D7: 1 | E7: 0 | F7: 0 | G7: 0
A8: Tổng số | B8: =SUM(B6:B7) -> 13 | C8: =SUM(C5:C7) -> 9 | D8: =SUM(D6:D7) -> 2 | E8: =SUM(E5:E7) -> 0 | F8: =SUM(F6:F7) -> 4 | G8: =SUM(G6:G7) -> 3
A9: 45540
A10: TopCV | B10: 1 | C10: 1 | D10: 1 | E10: 1 | F10: 0 | G10: 0
A11: Facebook | B11: 2 | C11: 2 | D11: 0 | E11: 0 | F11: 0 | G11: 0
A12: Tổng số | B12: =SUM(B10:B11) -> 3 | C12: =SUM(C9:C11) -> 3 | D12: =SUM(D10:D11) -> 1 | E12: =SUM(E9:E11) -> 1 | F12: 0 | G12: 0
A13: 45541
A14: TopCV | B14: 2 | C14: 2 | D14: 2 | E14: 2 | F14: 0 | G14: 0
A15: Facebook | B15: 0 | C15: 0 | D15: 0 | E15: 0 | F15: 0 | G15: 0
A16: Tổng số | B16: =SUM(B14:B15) -> 2 | C16: =SUM(C13:C15) -> 2 | D16: =SUM(D14:D15) -> 2 | E16: =SUM(E13:E15) -> 2 | F16: 0 | G16: 0
A17: 45544
A18: TopCV | B18: 7 | C18: 5 | D18: 2 | E18: 2 | F18: 0 | G18: 0
A19: Facebook | B19: 4 | C19: 4 | D19: 0 | E19: 0 | F19: 0 | G19: 0
A20: Tổng số | B20: =SUM(B18:B19) -> 11 | C20: =SUM(C17:C19) -> 9 | D20: =SUM(D18:D19) -> 2 | E20: =SUM(E17:E19) -> 2 | F20: 0 | G20: 0
A21: 45546
A22: TopCV | B22: 6 | C22: 5 | D22: 1 | E22: 1 | F22: 4 | G22: 4
A23: Facebook | B23: 0 | C23: 0 | D23: 0 | E23: 0 | F23: 0 | G23: 0
A24: Tổng số | B24: =SUM(B22:B23) -> 6 | C24: =SUM(C21:C23) -> 5 | D24: =SUM(D22:D23) -> 1 | E24: =SUM(E21:E23) -> 1 | F24: =SUM(F22:F23) -> 4 | G24: =SUM(G22:G23) -> 4
A25: 45547
A26: TopCV | B26: 5 | C26: 5 | D26: 0 | E26: 0 | F26: 0 | G26: 0
A27: Facebook | B27: 1 | C27: 1 | D27: 0 | E27: 0 | F27: 0 | G27: 0
A28: Tổng số | B28: =SUM(B26:B27) -> 6 | C28: =SUM(C25:C27) -> 6 | D28: 0 | E28: =SUM(E25:E27) -> 0 | F28: 0 | G28: 0
A29: 45552
A30: TopCV | B30: 15 | C30: 11 | D30: 0 | E30: 0 | F30: 3 | G30: 3
A31: Facebook | B31: 0 | C31: 0 | D31: 0 | E31: 0 | F31: 0 | G31: 0
A32: Tổng số | B32: =SUM(B30:B31) -> 15 | C32: =SUM(C30:C31) -> 11 | D32: =SUM(D30:D31) -> 0 | E32: =SUM(E30:E31) -> 0 | F32: =SUM(F30:F31) -> 3 | G32: =SUM(G30:G31) -> 3
A33: 45553
A34: TopCV | B34: 2 | C34: 2 | D34: 1 | E34: 0 | F34: 0 | G34: 0
A35: Facebook | B35: 0 | C35: 0 | D35: 0 | E35: 0 | F35: 0 | G35: 0
A36: Tổng số | B36: =SUM(B34:B35) -> 2 | C36: =SUM(C34:C35) -> 2 | D36: =SUM(D34:D35) -> 1 | E36: =SUM(E34:E35) -> 0 | F36: =SUM(F34:F35) -> 0 | G36: =SUM(G34:G35) -> 0
A37: 45554
A38: TopCV | B38: 5 | C38: 3 | D38: 5 | E38: 5 | F38: 0 | G38: 0
A39: Facebook | B39: 0 | C39: 0 | D39: 0 | E39: 0 | F39: 0 | G39: 0
A40: Tổng số | B40: =SUM(B38:B39) -> 5 | C40: =SUM(C38:C39) -> 3 | D40: =SUM(D38:D39) -> 5 | E40: =SUM(E38:E39) -> 5 | F40: =SUM(F38:F39) -> 0 | G40: =SUM(G38:G39) -> 0
A41: 45559
A42: TopCV | B42: 2 | C42: 2 | D42: 2 | E42: 2 | F42: 0 | G42: 3
...

Sheet T112024 BC TTS 
A2: MẪU BÁO CÁO TUYỂN DỤNG TTS THEO THỜI GIAN THÁNG 11/2024
A4: Nguồn | B4: Số hồ sơ nhận được | C4: Số hồ sơ đạt yêu cầu | D4: Số lượng tham gia PV | E4: Số lượng đạt PV | F4: Số lượng nhận việc | G4: Số lượng làm chính thức
A5: 45600
A6: TopCV | B6: 0 | C6: 0 | D6: 0 | E6: 0 | F6: 0 | G6: 0
A7: Facebook | B7: 0 | C7: 0 | D7: 0 | E7: 0 | F7: 0 | G7: 0
A8: Tiktok | B8: 0 | C8: 0 | D8: 0 | E8: 0 | F8: 0 | G8: 0
A9: Tổng số | B9: =SUM(B6:B8) -> 0 | C9: =SUM(C6:C8) -> 0 | D9: =SUM(D6:D8) -> 0 | E9: =SUM(E6:E8) -> 0 | F9: =SUM(F6:F8) -> 0 | G9: =SUM(G6:G8) -> 0
A10: 45601
A11: TopCV | B11: 0 | C11: 0 | D11: 0 | E11: 0 | F11: 0 | G11: 0
A12: Facebook | B12: 0 | C12: 0 | D12: 0 | E12: 0 | F12: 0 | G12: 0
A13: Tiktok | B13: 0 | C13: 0 | D13: 0 | E13: 0 | F13: 0 | G13: 0
A14: Tổng số | B14: =SUM(B11:B13) -> 0 | C14: =SUM(C11:C13) -> 0 | D14: =SUM(D11:D13) -> 0 | E14: =SUM(E11:E13) -> 0 | F14: =SUM(F11:F13) -> 0 | G14: =SUM(G11:G13) -> 0
A15: 45602
A16: TopCV | B16: 0 | C16: 0 | D16: 0 | E16: 0 | F16: 0 | G16: 0
A17: Facebook | B17: 0 | C17: 0 | D17: 0 | E17: 0 | F17: 0 | G17: 0
A18: Tiktok | B18: 0 | C18: 0 | D18: 0 | E18: 0 | F18: 0 | G18: 0
A19: Tổng số | B19: =SUM(B16:B18) -> 0 | C19: =SUM(C16:C18) -> 0 | D19: =SUM(D16:D18) -> 0 | E19: =SUM(E16:E18) -> 0 | F19: =SUM(F16:F18) -> 0 | G19: =SUM(G16:G18) -> 0
A20: 45607
A21: TopCV | B21: 0 | C21: 0 | D21: 0 | E21: 0 | F21: 0 | G21: 0
A22: Facebook | B22: 0 | C22: 0 | D22: 0 | E22: 0 | F22: 0 | G22: 0
A23: Tiktok | B23: 0 | C23: 0 | D23: 0 | E23: 0 | F23: 0 | G23: 0
A24: Tổng số | B24: =SUM(B21:B23) -> 0 | C24: =SUM(C21:C23) -> 0 | D24: =SUM(D21:D23) -> 0 | E24: =SUM(E21:E23) -> 0 | F24: =SUM(F21:F23) -> 0 | G24: =SUM(G21:G23) -> 0
A25: 45608
A26: TopCV | B26: 0 | C26: 0 | D26: 0 | E26: 0 | F26: 0 | G26: 0
A27: Facebook | B27: 0 | C27: 0 | D27: 0 | E27: 0 | F27: 0 | G27: 0
A28: Tiktok | B28: 0 | C28: 0 | D28: 0 | E28: 0 | F28: 0 | G28: 0
A29: Tổng số | B29: =SUM(B26:B28) -> 0 | C29: =SUM(C26:C28) -> 0 | D29: =SUM(D26:D28) -> 0 | E29: =SUM(E26:E28) -> 0 | F29: =SUM(F26:F28) -> 0 | G29: =SUM(G26:G28) -> 0
A30: 45615
A31: TopCV | B31: 4 | C31: 3 | D31: 0 | E31: 0 | F31: 0 | G31: 0
A32: Facebook | B32: 0 | C32: 0 | D32: 0 | E32: 0 | F32: 0 | G32: 0
A33: Tiktok | B33: 0 | C33: 0 | D33: 0 | E33: 0 | F33: 0 | G33: 0
A34: Tổng số | B34: =SUM(B31:B32) -> 4 | C34: =SUM(C31:C32) -> 3 | D34: =SUM(D31:D32) -> 0 | E34: =SUM(E31:E32) -> 0 | F34: =SUM(F31:F32) -> 0 | G34: =SUM(G31:G32) -> 0
A35: 45616
A36: TopCV | B36: 0 | C36: 0 | D36: 0 | E36: 0 | F36: 0 | G36: 0
A37: Facebook | B37: 0 | C37: 0 | D37: 0 | E37: 0 | F37: 0 | G37: 0
A38: Tiktok | B38: 0 | C38: 0 | D38: 0 | E38: 0 | F38: 0 | G38: 0
A39: Tổng số | B39: =SUM(B36:B38) -> 0 | C39: =SUM(C36:C38) -> 0 | D39: =SUM(D36:D38) -> 0 | E39: =SUM(E36:E38) -> 0 | F39: =SUM(F36:F38) -> 0 | G39: =SUM(G36:G38) -> 0
A40: 45617
A41: TopCV | B41: 0 | C41: 0 | D41: 0 | E41: 0 | F41: 0 | G41: 0
A42: Facebook | B42: 0 | C42: 0 | D42: 0 | E42: 0 | F42: 0 | G42: 0
...

Sheet T012025 BC TTS 
A2: MẪU BÁO CÁO TUYỂN DỤNG TTS THEO THỜI GIAN THÁNG 11/2024
A4: Nguồn | B4: Số hồ sơ nhận được | C4: Số hồ sơ đạt yêu cầu | D4: Số lượng tham gia PV | E4: Số lượng đạt PV | F4: Số lượng nhận việc | G4: Số lượng làm chính thức
A5: 45600
A6: TopCV | B6: 0 | C6: 0 | D6: 0 | E6: 0 | F6: 0 | G6: 0
A7: Facebook | B7: 0 | C7: 0 | D7: 0 | E7: 0 | F7: 0 | G7: 0
A8: Tiktok | B8: 0 | C8: 0 | D8: 0 | E8: 0 | F8: 0 | G8: 0
A9: Tổng số | B9: =SUM(B6:B8) -> 0 | C9: =SUM(C6:C8) -> 0 | D9: =SUM(D6:D8) -> 0 | E9: =SUM(E6:E8) -> 0 | F9: =SUM(F6:F8) -> 0 | G9: =SUM(G6:G8) -> 0
A10: 45601
A11: TopCV | B11: 0 | C11: 0 | D11: 0 | E11: 0 | F11: 0 | G11: 0
A12: Facebook | B12: 0 | C12: 0 | D12: 0 | E12: 0 | F12: 0 | G12: 0
A13: Tiktok | B13: 0 | C13: 0 | D13: 0 | E13: 0 | F13: 0 | G13: 0
A14: Tổng số | B14: =SUM(B11:B13) -> 0 | C14: =SUM(C11:C13) -> 0 | D14: =SUM(D11:D13) -> 0 | E14: =SUM(E11:E13) -> 0 | F14: =SUM(F11:F13) -> 0 | G14: =SUM(G11:G13) -> 0
A15: 45602
A16: TopCV | B16: 0 | C16: 0 | D16: 0 | E16: 0 | F16: 0 | G16: 0
A17: Facebook | B17: 0 | C17: 0 | D17: 0 | E17: 0 | F17: 0 | G17: 0
A18: Tiktok | B18: 0 | C18: 0 | D18: 0 | E18: 0 | F18: 0 | G18: 0
A19: Tổng số | B19: =SUM(B16:B18) -> 0 | C19: =SUM(C16:C18) -> 0 | D19: =SUM(D16:D18) -> 0 | E19: =SUM(E16:E18) -> 0 | F19: =SUM(F16:F18) -> 0 | G19: =SUM(G16:G18) -> 0
A20: 45607
A21: TopCV | B21: 0 | C21: 0 | D21: 0 | E21: 0 | F21: 0 | G21: 0
A22: Facebook | B22: 0 | C22: 0 | D22: 0 | E22: 0 | F22: 0 | G22: 0
A23: Tiktok | B23: 0 | C23: 0 | D23: 0 | E23: 0 | F23: 0 | G23: 0
A24: Tổng số | B24: =SUM(B21:B23) -> 0 | C24: =SUM(C21:C23) -> 0 | D24: =SUM(D21:D23) -> 0 | E24: =SUM(E21:E23) -> 0 | F24: =SUM(F21:F23) -> 0 | G24: =SUM(G21:G23) -> 0
A25: 45608
A26: TopCV | B26: 0 | C26: 0 | D26: 0 | E26: 0 | F26: 0 | G26: 0
A27: Facebook | B27: 0 | C27: 0 | D27: 0 | E27: 0 | F27: 0 | G27: 0
A28: Tiktok | B28: 0 | C28: 0 | D28: 0 | E28: 0 | F28: 0 | G28: 0
A29: Tổng số | B29: =SUM(B26:B28) -> 0 | C29: =SUM(C26:C28) -> 0 | D29: =SUM(D26:D28) -> 0 | E29: =SUM(E26:E28) -> 0 | F29: =SUM(F26:F28) -> 0 | G29: =SUM(G26:G28) -> 0
A30: 45615
A31: TopCV | B31: 4 | C31: 3 | D31: 0 | E31: 0 | F31: 0 | G31: 0
A32: Facebook | B32: 0 | C32: 0 | D32: 0 | E32: 0 | F32: 0 | G32: 0
A33: Tiktok | B33: 0 | C33: 0 | D33: 0 | E33: 0 | F33: 0 | G33: 0
A34: Tổng số | B34: =SUM(B31:B32) -> 4 | C34: =SUM(C31:C32) -> 3 | D34: =SUM(D31:D32) -> 0 | E34: =SUM(E31:E32) -> 0 | F34: =SUM(F31:F32) -> 0 | G34: =SUM(G31:G32) -> 0
A35: 45616
A36: TopCV | B36: 0 | C36: 0 | D36: 0 | E36: 0 | F36: 0 | G36: 0
A37: Facebook | B37: 0 | C37: 0 | D37: 0 | E37: 0 | F37: 0 | G37: 0
A38: Tiktok | B38: 0 | C38: 0 | D38: 0 | E38: 0 | F38: 0 | G38: 0
A39: Tổng số | B39: =SUM(B36:B38) -> 0 | C39: =SUM(C36:C38) -> 0 | D39: =SUM(D36:D38) -> 0 | E39: =SUM(E36:E38) -> 0 | F39: =SUM(F36:F38) -> 0 | G39: =SUM(G36:G38) -> 0
A40: 45617
A41: TopCV | B41: 0 | C41: 0 | D41: 0 | E41: 0 | F41: 0 | G41: 0
A42: Facebook | B42: 0 | C42: 0 | D42: 0 | E42: 0 | F42: 0 | G42: 0
...

Sheet T122024 BC TTS 
A2: MẪU BÁO CÁO TUYỂN DỤNG TTS THEO THỜI GIAN THÁNG 12/2024
A4: Nguồn | B4: Số hồ sơ nhận được | C4: Số hồ sơ đạt yêu cầu | D4: Số lượng tham gia PV | E4: Số lượng đạt PV | F4: Số lượng nhận việc | G4: Số lượng làm chính thức
A5: 45628
A6: TopCV | B6: 0 | C6: 0 | D6: 0 | E6: 0 | F6: 0 | G6: 0
A7: Facebook | B7: 0 | C7: 0 | D7: 0 | E7: 0 | F7: 0 | G7: 0
A8: Tiktok | B8: 0 | C8: 0 | D8: 0 | E8: 0 | F8: 0 | G8: 0
A9: Tổng số | B9: =SUM(B6:B8) -> 0 | C9: =SUM(C6:C8) -> 0 | D9: =SUM(D6:D8) -> 0 | E9: =SUM(E6:E8) -> 0 | F9: =SUM(F6:F8) -> 0 | G9: =SUM(G6:G8) -> 0
A10: 45629
A11: TopCV | B11: 0 | C11: 0 | D11: 0 | E11: 0 | F11: 0 | G11: 0
A12: Facebook | B12: 0 | C12: 0 | D12: 0 | E12: 0 | F12: 0 | G12: 0
A13: Tiktok | B13: 0 | C13: 0 | D13: 0 | E13: 0 | F13: 0 | G13: 0
A14: Tổng số | B14: =SUM(B11:B13) -> 0 | C14: =SUM(C11:C13) -> 0 | D14: =SUM(D11:D13) -> 0 | E14: =SUM(E11:E13) -> 0 | F14: =SUM(F11:F13) -> 0 | G14: =SUM(G11:G13) -> 0
A15: 45630
A16: TopCV | B16: 0 | C16: 0 | D16: 0 | E16: 0 | F16: 0 | G16: 0
A17: Facebook | B17: 0 | C17: 0 | D17: 0 | E17: 0 | F17: 0 | G17: 0
A18: Tiktok | B18: 0 | C18: 0 | D18: 0 | E18: 0 | F18: 0 | G18: 0
A19: Tổng số | B19: =SUM(B16:B18) -> 0 | C19: =SUM(C16:C18) -> 0 | D19: =SUM(D16:D18) -> 0 | E19: =SUM(E16:E18) -> 0 | F19: =SUM(F16:F18) -> 0 | G19: =SUM(G16:G18) -> 0
A20: 45631
A21: TopCV | B21: 1 | C21: 1 | D21: 0 | E21: 0 | F21: 0 | G21: 0
A22: Facebook | B22: 0 | C22: 0 | D22: 0 | E22: 0 | F22: 0 | G22: 0
A23: Tiktok | B23: 0 | C23: 0 | D23: 0 | E23: 0 | F23: 0 | G23: 0
A24: Tổng số | B24: =SUM(B21:B23) -> 1 | C24: =SUM(C21:C23) -> 1 | D24: =SUM(D21:D23) -> 0 | E24: =SUM(E21:E23) -> 0 | F24: =SUM(F21:F23) -> 0 | G24: =SUM(G21:G23) -> 0
A25: 45632
A26: TopCV | B26: 1 | C26: 0 | D26: 0 | E26: 0 | F26: 0 | G26: 0
A27: Facebook | B27: 0 | C27: 0 | D27: 0 | E27: 0 | F27: 0 | G27: 0
A28: Tiktok | B28: 0 | C28: 0 | D28: 0 | E28: 0 | F28: 0 | G28: 0
A29: Tổng số | B29: =SUM(B26:B28) -> 1 | C29: =SUM(C26:C28) -> 0 | D29: =SUM(D26:D28) -> 0 | E29: =SUM(E26:E28) -> 0 | F29: =SUM(F26:F28) -> 0 | G29: =SUM(G26:G28) -> 0
A30: 45633
A31: TopCV | B31: 0 | C31: 0 | D31: 0 | E31: 0 | F31: 0 | G31: 0
A32: Facebook | B32: 0 | C32: 0 | D32: 0 | E32: 0 | F32: 0 | G32: 0
A33: Tiktok | B33: 0 | C33: 0 | D33: 0 | E33: 0 | F33: 0 | G33: 0
A34: Tổng số | B34: =SUM(B31:B32) -> 0 | C34: =SUM(C31:C32) -> 0 | D34: =SUM(D31:D32) -> 0 | E34: =SUM(E31:E32) -> 0 | F34: =SUM(F31:F32) -> 0 | G34: =SUM(G31:G32) -> 0
A35: 45635
A36: TopCV | B36: 0 | C36: 0 | D36: 0 | E36: 0 | F36: 0 | G36: 0
A37: Facebook | B37: 0 | C37: 0 | D37: 0 | E37: 0 | F37: 0 | G37: 0
A38: Tiktok | B38: 0 | C38: 0 | D38: 0 | E38: 0 | F38: 0 | G38: 0
A39: Tổng số | B39: =SUM(B36:B38) -> 0 | C39: =SUM(C36:C38) -> 0 | D39: =SUM(D36:D38) -> 0 | E39: =SUM(E36:E38) -> 0 | F39: =SUM(F36:F38) -> 0 | G39: =SUM(G36:G38) -> 0
A40: 45636
A41: TopCV | B41: 0 | C41: 0 | D41: 0 | E41: 0 | F41: 0 | G41: 0
A42: Facebook | B42: 0 | C42: 0 | D42: 0 | E42: 0 | F42: 0 | G42: 0
...

Sheet T122024 BC CV
A2: MẪU BÁO CÁO TUYỂN DỤNG CVKD THEO THỜI GIAN THÁNG 12/2024
A4: Nguồn | B4: Số hồ sơ nhận được | C4: Số hồ sơ đạt yêu cầu | D4: Số lượng tham gia PV | E4: Số lượng đạt PV | F4: Số lượng nhận việc | G4: Số lượng làm chính thức
A5: 45628
A6: TopCV | B6: 0 | C6: 0 | D6: 0 | E6: 0 | F6: 0 | G6: 0
A7: Facebook | B7: 0 | C7: 0 | D7: 0 | E7: 0 | F7: 0 | G7: 0
A8: Tiktok | B8: 0 | C8: 0 | D8: 0 | E8: 0 | F8: 0 | G8: 0
A9: Tổng số | B9: =SUM(B6:B8) -> 0 | C9: =SUM(C6:C8) -> 0 | D9: =SUM(D6:D8) -> 0 | E9: =SUM(E6:E8) -> 0 | F9: =SUM(F6:F8) -> 0 | G9: =SUM(G6:G8) -> 0
A10: 45629
A11: TopCV | B11: 0 | C11: 0 | D11: 0 | E11: 0 | F11: 0 | G11: 0
A12: Facebook | B12: 0 | C12: 0 | D12: 0 | E12: 0 | F12: 0 | G12: 0
A13: Tiktok | B13: 0 | C13: 0 | D13: 0 | E13: 0 | F13: 0 | G13: 0
A14: Tổng số | B14: =SUM(B11:B13) -> 0 | C14: =SUM(C11:C13) -> 0 | D14: =SUM(D11:D13) -> 0 | E14: =SUM(E11:E13) -> 0 | F14: =SUM(F11:F13) -> 0 | G14: =SUM(G11:G13) -> 0
A15: 45630
A16: TopCV | B16: 0 | C16: 0 | D16: 0 | E16: 0 | F16: 0 | G16: 0
A17: Facebook | B17: 0 | C17: 0 | D17: 0 | E17: 0 | F17: 0 | G17: 0
A18: Tiktok | B18: 0 | C18: 0 | D18: 0 | E18: 0 | F18: 0 | G18: 0
A19: Tổng số | B19: =SUM(B16:B18) -> 0 | C19: =SUM(C16:C18) -> 0 | D19: =SUM(D16:D18) -> 0 | E19: =SUM(E16:E18) -> 0 | F19: =SUM(F16:F18) -> 0 | G19: =SUM(G16:G18) -> 0
A20: 45631
A21: TopCV | B21: 1 | C21: 0 | D21: 0 | E21: 0 | F21: 0 | G21: 0
A22: Facebook | B22: 0 | C22: 0 | D22: 0 | E22: 0 | F22: 0 | G22: 0
A23: Tiktok | B23: 0 | C23: 0 | D23: 0 | E23: 0 | F23: 0 | G23: 0
A24: Tổng số | B24: =SUM(B21:B23) -> 1 | C24: =SUM(C21:C23) -> 0 | D24: =SUM(D21:D23) -> 0 | E24: =SUM(E21:E23) -> 0 | F24: =SUM(F21:F23) -> 0 | G24: =SUM(G21:G23) -> 0
A25: 45632
A26: TopCV | B26: 0 | C26: 0 | D26: 0 | E26: 0 | F26: 0 | G26: 0
A27: Facebook | B27: 0 | C27: 0 | D27: 0 | E27: 0 | F27: 0 | G27: 0
A28: Tiktok | B28: 0 | C28: 0 | D28: 0 | E28: 0 | F28: 0 | G28: 0
A29: Tổng số | B29: =SUM(B26:B28) -> 0 | C29: =SUM(C26:C28) -> 0 | D29: =SUM(D26:D28) -> 0 | E29: =SUM(E26:E28) -> 0 | F29: =SUM(F26:F28) -> 0 | G29: =SUM(G26:G28) -> 0
A30: 45633
A31: TopCV | B31: 0 | C31: 0 | D31: 0 | E31: 0 | F31: 0 | G31: 0
A32: Facebook | B32: 0 | C32: 0 | D32: 0 | E32: 0 | F32: 0 | G32: 0
A33: Tiktok | B33: 0 | C33: 0 | D33: 0 | E33: 0 | F33: 0 | G33: 0
A34: Tổng số | B34: =SUM(B31:B32) -> 0 | C34: =SUM(C31:C32) -> 0 | D34: =SUM(D31:D32) -> 0 | E34: =SUM(E31:E32) -> 0 | F34: =SUM(F31:F32) -> 0 | G34: =SUM(G31:G32) -> 0
A35: 45635
A36: TopCV | B36: 1 | C36: 0 | D36: 0 | E36: 0 | F36: 0 | G36: 0
A37: Facebook | B37: 0 | C37: 0 | D37: 0 | E37: 0 | F37: 0 | G37: 0
A38: Tiktok | B38: 0 | C38: 0 | D38: 0 | E38: 0 | F38: 0 | G38: 0
A39: Tổng số | B39: =SUM(B36:B38) -> 1 | C39: =SUM(C36:C38) -> 0 | D39: =SUM(D36:D38) -> 0 | E39: =SUM(E36:E38) -> 0 | F39: =SUM(F36:F38) -> 0 | G39: =SUM(G36:G38) -> 0
A40: 45636
A41: TopCV | B41: 0 | C41: 0 | D41: 0 | E41: 0 | F41: 0 | G41: 0
A42: Facebook | B42: 0 | C42: 0 | D42: 0 | E42: 0 | F42: 0 | G42: 0
...

Sheet T112024 BC CV 
A2: MẪU BÁO CÁO TUYỂN DỤNG CVKD THEO THỜI GIAN THÁNG 11/2024
A4: Nguồn | B4: Số hồ sơ nhận được | C4: Số hồ sơ đạt yêu cầu | D4: Số lượng tham gia PV | E4: Số lượng đạt PV | F4: Số lượng nhận việc | G4: Số lượng làm chính thức
A5: 45600
A6: TopCV | B6: 0 | C6: 0 | D6: 0 | E6: 0 | F6: 0 | G6: 0
A7: Facebook | B7: 0 | C7: 0 | D7: 0 | E7: 0 | F7: 0 | G7: 0
A8: Tiktok | B8: 0 | C8: 0 | D8: 0 | E8: 0 | F8: 0 | G8: 0
A9: Tổng số | B9: =SUM(B6:B8) -> 0 | C9: =SUM(C6:C8) -> 0 | D9: =SUM(D6:D8) -> 0 | E9: =SUM(E6:E8) -> 0 | F9: =SUM(F6:F8) -> 0 | G9: =SUM(G6:G8) -> 0
A10: 45601
A11: TopCV | B11: 0 | C11: 0 | D11: 0 | E11: 0 | F11: 0 | G11: 0
A12: Facebook | B12: 0 | C12: 0 | D12: 0 | E12: 0 | F12: 0 | G12: 0
A13: Tiktok | B13: 0 | C13: 0 | D13: 0 | E13: 0 | F13: 0 | G13: 0
A14: Tổng số | B14: =SUM(B11:B13) -> 0 | C14: =SUM(C11:C13) -> 0 | D14: =SUM(D11:D13) -> 0 | E14: =SUM(E11:E13) -> 0 | F14: =SUM(F11:F13) -> 0 | G14: =SUM(G11:G13) -> 0
A15: 45602
A16: TopCV | B16: 0 | C16: 0 | D16: 0 | E16: 0 | F16: 0 | G16: 0
A17: Facebook | B17: 0 | C17: 0 | D17: 0 | E17: 0 | F17: 0 | G17: 0
A18: Tiktok | B18: 0 | C18: 0 | D18: 0 | E18: 0 | F18: 0 | G18: 0
A19: Tổng số | B19: =SUM(B16:B18) -> 0 | C19: =SUM(C16:C18) -> 0 | D19: =SUM(D16:D18) -> 0 | E19: =SUM(E16:E18) -> 0 | F19: =SUM(F16:F18) -> 0 | G19: =SUM(G16:G18) -> 0
A20: 45607
A21: TopCV | B21: 0 | C21: 0 | D21: 0 | E21: 0 | F21: 0 | G21: 0
A22: Facebook | B22: 0 | C22: 0 | D22: 0 | E22: 0 | F22: 0 | G22: 0
A23: Tiktok | B23: 0 | C23: 0 | D23: 0 | E23: 0 | F23: 0 | G23: 0
A24: Tổng số | B24: =SUM(B21:B23) -> 0 | C24: =SUM(C21:C23) -> 0 | D24: =SUM(D21:D23) -> 0 | E24: =SUM(E21:E23) -> 0 | F24: =SUM(F21:F23) -> 0 | G24: =SUM(G21:G23) -> 0
A25: 45608
A26: TopCV | B26: 0 | C26: 0 | D26: 0 | E26: 0 | F26: 0 | G26: 0
A27: Facebook | B27: 0 | C27: 0 | D27: 0 | E27: 0 | F27: 0 | G27: 0
A28: Tiktok | B28: 0 | C28: 0 | D28: 0 | E28: 0 | F28: 0 | G28: 0
A29: Tổng số | B29: =SUM(B26:B28) -> 0 | C29: =SUM(C26:C28) -> 0 | D29: =SUM(D26:D28) -> 0 | E29: =SUM(E26:E28) -> 0 | F29: =SUM(F26:F28) -> 0 | G29: =SUM(G26:G28) -> 0
A30: 45615
A31: TopCV | B31: 1 | C31: 0 | D31: 0 | E31: 0 | F31: 0 | G31: 0
A32: Facebook | B32: 0 | C32: 0 | D32: 0 | E32: 0 | F32: 0 | G32: 0
A33: Tiktok | B33: 0 | C33: 0 | D33: 0 | E33: 0 | F33: 0 | G33: 0
A34: Tổng số | B34: =SUM(B31:B32) -> 1 | C34: =SUM(C31:C32) -> 0 | D34: =SUM(D31:D32) -> 0 | E34: =SUM(E31:E32) -> 0 | F34: =SUM(F31:F32) -> 0 | G34: =SUM(G31:G32) -> 0
A35: 45616
A36: TopCV | B36: 0 | C36: 0 | D36: 0 | E36: 0 | F36: 0 | G36: 0
A37: Facebook | B37: 0 | C37: 0 | D37: 0 | E37: 0 | F37: 0 | G37: 0
A38: Tiktok | B38: 0 | C38: 0 | D38: 0 | E38: 0 | F38: 0 | G38: 0
A39: Tổng số | B39: =SUM(B36:B38) -> 0 | C39: =SUM(C36:C38) -> 0 | D39: =SUM(D36:D38) -> 0 | E39: =SUM(E36:E38) -> 0 | F39: =SUM(F36:F38) -> 0 | G39: =SUM(G36:G38) -> 0
A40: 45617
A41: TopCV | B41: 0 | C41: 0 | D41: 0 | E41: 0 | F41: 0 | G41: 0
A42: Facebook | B42: 1 | C42: 1 | D42: 0 | E42: 0 | F42: 0 | G42: 0
...

Sheet T012025 BC CV 
A2: MẪU BÁO CÁO TUYỂN DỤNG CVKD THEO THỜI GIAN THÁNG 11/2024
A4: Nguồn | B4: Số hồ sơ nhận được | C4: Số hồ sơ đạt yêu cầu | D4: Số lượng tham gia PV | E4: Số lượng đạt PV | F4: Số lượng nhận việc | G4: Số lượng làm chính thức
A5: 45600
A6: TopCV | B6: 0 | C6: 0 | D6: 0 | E6: 0 | F6: 0 | G6: 0
A7: Facebook | B7: 0 | C7: 0 | D7: 0 | E7: 0 | F7: 0 | G7: 0
A8: Tiktok | B8: 0 | C8: 0 | D8: 0 | E8: 0 | F8: 0 | G8: 0
A9: Tổng số | B9: =SUM(B6:B8) -> 0 | C9: =SUM(C6:C8) -> 0 | D9: =SUM(D6:D8) -> 0 | E9: =SUM(E6:E8) -> 0 | F9: =SUM(F6:F8) -> 0 | G9: =SUM(G6:G8) -> 0
A10: 45601
A11: TopCV | B11: 0 | C11: 0 | D11: 0 | E11: 0 | F11: 0 | G11: 0
A12: Facebook | B12: 0 | C12: 0 | D12: 0 | E12: 0 | F12: 0 | G12: 0
A13: Tiktok | B13: 0 | C13: 0 | D13: 0 | E13: 0 | F13: 0 | G13: 0
A14: Tổng số | B14: =SUM(B11:B13) -> 0 | C14: =SUM(C11:C13) -> 0 | D14: =SUM(D11:D13) -> 0 | E14: =SUM(E11:E13) -> 0 | F14: =SUM(F11:F13) -> 0 | G14: =SUM(G11:G13) -> 0
A15: 45602
A16: TopCV | B16: 0 | C16: 0 | D16: 0 | E16: 0 | F16: 0 | G16: 0
A17: Facebook | B17: 0 | C17: 0 | D17: 0 | E17: 0 | F17: 0 | G17: 0
A18: Tiktok | B18: 0 | C18: 0 | D18: 0 | E18: 0 | F18: 0 | G18: 0
A19: Tổng số | B19: =SUM(B16:B18) -> 0 | C19: =SUM(C16:C18) -> 0 | D19: =SUM(D16:D18) -> 0 | E19: =SUM(E16:E18) -> 0 | F19: =SUM(F16:F18) -> 0 | G19: =SUM(G16:G18) -> 0
A20: 45607
A21: TopCV | B21: 0 | C21: 0 | D21: 0 | E21: 0 | F21: 0 | G21: 0
A22: Facebook | B22: 0 | C22: 0 | D22: 0 | E22: 0 | F22: 0 | G22: 0
A23: Tiktok | B23: 0 | C23: 0 | D23: 0 | E23: 0 | F23: 0 | G23: 0
A24: Tổng số | B24: =SUM(B21:B23) -> 0 | C24: =SUM(C21:C23) -> 0 | D24: =SUM(D21:D23) -> 0 | E24: =SUM(E21:E23) -> 0 | F24: =SUM(F21:F23) -> 0 | G24: =SUM(G21:G23) -> 0
A25: 45608
A26: TopCV | B26: 0 | C26: 0 | D26: 0 | E26: 0 | F26: 0 | G26: 0
A27: Facebook | B27: 0 | C27: 0 | D27: 0 | E27: 0 | F27: 0 | G27: 0
A28: Tiktok | B28: 0 | C28: 0 | D28: 0 | E28: 0 | F28: 0 | G28: 0
A29: Tổng số | B29: =SUM(B26:B28) -> 0 | C29: =SUM(C26:C28) -> 0 | D29: =SUM(D26:D28) -> 0 | E29: =SUM(E26:E28) -> 0 | F29: =SUM(F26:F28) -> 0 | G29: =SUM(G26:G28) -> 0
A30: 45615
A31: TopCV | B31: 4 | C31: 3 | D31: 0 | E31: 0 | F31: 0 | G31: 0
A32: Facebook | B32: 0 | C32: 0 | D32: 0 | E32: 0 | F32: 0 | G32: 0
A33: Tiktok | B33: 0 | C33: 0 | D33: 0 | E33: 0 | F33: 0 | G33: 0
A34: Tổng số | B34: =SUM(B31:B32) -> 4 | C34: =SUM(C31:C32) -> 3 | D34: =SUM(D31:D32) -> 0 | E34: =SUM(E31:E32) -> 0 | F34: =SUM(F31:F32) -> 0 | G34: =SUM(G31:G32) -> 0
A35: 45616
A36: TopCV | B36: 0 | C36: 0 | D36: 0 | E36: 0 | F36: 0 | G36: 0
A37: Facebook | B37: 0 | C37: 0 | D37: 0 | E37: 0 | F37: 0 | G37: 0
A38: Tiktok | B38: 0 | C38: 0 | D38: 0 | E38: 0 | F38: 0 | G38: 0
A39: Tổng số | B39: =SUM(B36:B38) -> 0 | C39: =SUM(C36:C38) -> 0 | D39: =SUM(D36:D38) -> 0 | E39: =SUM(E36:E38) -> 0 | F39: =SUM(F36:F38) -> 0 | G39: =SUM(G36:G38) -> 0
A40: 45617
A41: TopCV | B41: 0 | C41: 0 | D41: 0 | E41: 0 | F41: 0 | G41: 0
A42: Facebook | B42: 0 | C42: 0 | D42: 0 | E42: 0 | F42: 0 | G42: 0
...
