Workbook

Sheet Năm
A1: Tháng | B1: Năm | C1: Số dư đầu kỳ | D1: Thu | E1: Chi | F1: Số dư cuối kỳ | G1: Lợi nhuận
A2: Tháng 1 | B2: 2026 | C2: 0 | D2: ='T1'!C7 -> 299439459 | E2: ='T1'!$D$7 -> 259193146 | F2: =C2+D2-E2 -> 40246313 | G2: =D2-E2 -> 40246313
A3: Tháng 2 | B3: 2025 | C3: =F2 -> 40246313 | D3: ='T2'!C7 -> 83099693 | E3: ='T2'!$D$7 -> 142261299 | F3: =C3+D3-E3 -> -18915293 | G3: =D3-E3 -> -59161606
A4: Tháng 3 | B4: 2025 | C4: =F3 -> -18915293 | D4: ='T3'!C7 -> 490340000 | E4: ='T3'!$D$7 -> 96449060 | F4: =C4+D4-E4 -> 374975647 | G4: =D4-E4 -> 393890940
A5: Tháng 4 | B5: 2025 | C5: =F4 -> 374975647 | D5: ='T4'!C7 -> 0 | E5: ='T4'!$D$7 -> 77759355 | F5: =C5+D5-E5 -> 297216292 | G5: =D5-E5 -> -77759355
A6: Tháng 5 | B6: 2025 | C6: =F5 -> 297216292 | D6: ='T5'!C7 -> 0 | E6: ='T5'!$D$7 -> 96031632 | F6: =C6+D6-E6 -> 201184660 | G6: =D6-E6 -> -96031632
A7: Tháng 6 | B7: 2025 | C7: =F6 -> 201184660 | D7: ='T6'!C7 -> 30000000 | E7: ='T6'!$D$7 -> 147431580 | F7: =C7+D7-E7 -> 83753080 | G7: =D7-E7 -> -117431580
A8: Tháng 7 | B8: 2025 | C8: =F7 -> 83753080 | D8: ='T7'!C7 -> 418072941 | E8: ='T7'!$D$7 -> 222170084 | F8: =C8+D8-E8 -> 279655937 | G8: =D8-E8 -> 195902857
A9: Tháng 8 | B9: 2025 | C9: =F8 -> 279655937 | D9: ='T8'!C7 -> 69942464 | E9: ='T8'!$D$7 -> 408832810 | F9: =C9+D9-E9 -> -59234409 | G9: =D9-E9 -> -338890346
A10: Tháng 9 | B10: 2025 | C10: =F9 -> -59234409 | D10: ='T9'!C7 -> 100000000 | E10: ='T1'!$D$7 -> 259193146 | F10: =C10+D10-E10 -> -218427555 | G10: =D10-E10 -> -159193146
A11: Tháng 10 | B11: 2025 | C11: =F10 -> -218427555 | D11: ='T10'!C7 -> 472747966 | E11: ='T1'!$D$7 -> 259193146 | F11: =C11+D11-E11 -> -4872735 | G11: =D11-E11 -> 213554820
A12: Tháng 11 | B12: 2025 | C12: =F11 -> -4872735 | D12: ='T11'!C7 -> 158028579 | E12: ='T1'!$D$7 -> 259193146 | F12: =C12+D12-E12 -> -106037302 | G12: =D12-E12 -> -101164567
A13: Tháng 12 | B13: 2025 | C13: =F12 -> -106037302 | D13: ='T12'!C7 -> 295697978 | E13: ='T1'!$D$7 -> 259193146 | F13: =C13+D13-E13 -> -69532470 | G13: =D13-E13 -> 36504832

Sheet T1
A1: I. Theo dõi khoản thu - chi (nhập mỗi ngày) | H1: II. Báo cáo kết quả hoạt động kinh doanh (25 hàng tháng)
A2: KHOẢN THU - CHI THÁNG T1/2025 | H2: KHOẢN | I2: DIỄN GIẢI | J2: Số tiền
A3: STT | B3: Ngày | C3: Số tiền | E3: KHOẢN | F3: DIỄN GIẢI | H3: 1 | I3: Doanh thu | J3: =SUM(J4:J6) -> 299439459
C4: THU | D4: CHI | H4: 1.1 | I4: Doanh thu bán hàng | J4: =SUMIF($E$8:$E$54,1.1,$C$8:$C$45) -> 299439459
H5: 1.2 | I5: Khoản thu bán hàng khác | J5: =SUMIF($E$8:$E$54,1.2,$C$8:$C$45) -> 0
H6: 1.3 | I6: Các khoản giảm trừ DT (ưu đãi, …) | J6: =SUMIF($E$8:$E$54,1.3,$C$8:$C$45) -> 0
C7: =SUM(C8:C66) -> 299439459 | D7: =SUM(D8:D66) -> 259193146 | G7: Lọc
A8: 1 | B8: 45679 | D8: 9000000 | E8: 2,5 | F8: Thưởng nóng Da Lavida B2.0606 NV Lê Kiều Loan | H8: 2 | I8: Chi phí | J8: =SUM(J9:J19) -> 259193146
A9: 2 | B9: 45679 | D9: 28605142 | E9: 2,5 | F9: HH đợt 1 Da Lavida B2.0606 NV Lê Kiều Loan | H9: 2.1 | I9: Giá vốn hàng bán | J9: =SUMIF($E$8:$E$54,2.1,$D$8:$D$45) -> 0
A10: 3 | B10: 45663 | D10: 117798939 | E10: 2,2 | F10: lương T12.24 | H10: 2.2 | I10: Chi phí Lương | J10: =SUMIF($E$8:$E$54,2.2,$D$8:$D$45) -> 117798939
A11: 4 | B11: 45663 | D11: 41799387 | E11: 2,6 | F11: Thuê vp T1.25 | H11: 2.3 | I11: Chi phí TT MKT | J11: =SUMIF($E$8:$E$54,2.3,$D$8:$D$45) -> 2000000
A12: 5 | B12: 45666 | D12: 1093520 | E12: 2,7 | F12: Chi phí vận hành văn phòng | H12: 2.4 | I12: Chi phí tuyển dụng | J12: =SUMIF($E$8:$E$54,2.4,$D$8:$D$45) -> 0
A13: 6 | B13: 45679 | D13: 12698616 | E13: 2,5 | F13: HH đợt 1 Da Lavida B2.0621 NV Nguyễn Thị Mơ | H13: 2.5 | I13: Chi phí vận hành bán hàng | J13: =SUMIF($E$8:$E$54,2.5,$D$8:$D$45) -> 69501300
A14: 7 | B14: 45679 | D14: 16832542 | E14: 2,5 | F14: HH đợt 1 Da Lavida B1.0403 NV Nguyễn Hữu Nam | H14: 2.6 | I14: Tiền nhà | J14: =SUMIF($E$8:$E$54,2.6,$D$8:$D$45) -> 41799387
A15: 8 | B15: 45660 | D15: 1500000 | E15: 2,5 | F15: Tạm ứng phí ctac Bình Thuận 03.01.25 | H15: 2.7 | I15: Chi phí vận hành khác (điện, nước, internet, điện thoại, văn phòng phẩm …) | J15: =SUMIF($E$8:$E$54,2.7,$D$8:$D$45) -> 1093520
A16: 9 | B16: 45663 | D16: -195000 | E16: 2,5 | F16: Hoàn tiền tạm ứng phí ctac Bình Thuận 03.01.25 | H16: 2.8 | I16: Khoản vay | J16: =SUMIF($E$8:$E$54,2.8,$D$8:$D$45) -> 27000000
A17: 10 | B17: 45663 | D17: 27000000 | E17: 2,8 | F17: Thanh toán khoản vay oto | H17: 2.9 | I17: BHXH | J17: =SUMIF($E$8:$E$54,2.9,$D$8:$D$45) -> 0
A18: 11 | B18: 45660 | D18: 1060000 | E18: 2,5 | F18: Phí dịch vụ hồ sơ sổ 6912 CL và 1810,8 PRT | H18: 2.11 | I18: Chi phí khác | J18: =SUMIF($E$8:$E$54,2.11,$D$8:$D$45) -> 0
A19: 12 | B19: 45664 | C19: 99919883 | E19: 1,1 | F19: VAREAL THANH TOAN PHI MOI GIOI THANG 11 GD2 DU AN LAVIDA+ HOA DON SO 2 CHO CONG TY LONG HOANG INVESTMENT | H19: 2.12 | I19: Khoảng chi bán hàng khác (hoàn tiền,đặt chỗ) | J19: =SUMIF($E$8:$E$54,2.12,$D$8:$D$45) -> 0
A20: 13 | B20: 45663 | D20: 1000000 | E20: 2,3 | F20: Nạp tiền bds.com | H20: 3 | I20: Lợi nhuận (trước Thuế) | J20: =J3-J8 -> 40246313
A21: 14 | B21: 45671 | D21: 1000000 | E21: 2,3 | F21: Nạp tiền bds.com
A22: 15 | B22: 45679 | C22: 11000000 | E22: 1,1 | F22: THANH TOAN THUONG NONG CAN B2.0606- DA LAVIDA+ ( HD 1 NGAY 10/01/25) | H22: III. Báo cáo lưu chuyển tiền tệ ( 25 hàng tháng )
A23: 16 | B23: 45679 | C23: 77599693 | E23: 1,1 | F23: THANH TOAN PHI MOI GIOI CAN B2.0606- DA LAVIDA+ ( HD 2 NGAY 10/01/25) | I23: DIỄN GIẢI | J23: Số tiền
A24: 17 | B24: 45682 | C24: 110919883 | E24: 1,1 | F24: VAREAL THANH TOAN PHI MOI GIOI THANG 12 GD2 DU AN LAVIDA+ HOA DON SO 3 CHO CONG TY LONG HOANG INVESTMENT | H24: A | I24: Số dư đầu kỳ (Tồn quỹ đầu kỳ) | J24: 0
A25: 18 | H25: B | I25: Phát sinh tăng trong kỳ | J25: =SUM(J26:J28) -> 299439459
A26: 19 | I26: Doanh thu bán hàng thực thu | J26: =J3 -> 299439459
A27: 20 | I27: Thu hồi công nợ
A28: 21 | I28: Đi vay
A29: 22 | H29: C | I29: Phát sinh giảm trong kỳ | J29: =SUM(J30:J41) -> 259193146
A30: 23 | H30: 2.1 | I30: Giá vốn hàng bán | J30: =J9 -> 0
A31: 24 | H31: 1.3 | I31: Khoảng chi bán hàng chiết khấu , ưu đãi
A32: 25 | H32: 2.2 | I32: Chi phí Lương | J32: =J10 -> 117798939
A33: 26 | H33: 2.3 | I33: Chi phí TT MKT | J33: =J11 -> 2000000
A34: 27 | H34: 2.4 | I34: Chi phí tuyển dụng | J34: =J12 -> 0
A35: 28 | H35: 2.5 | I35: Chi phí vận hành bán hàng | J35: =J13 -> 69501300
A36: 29 | H36: 2.6 | I36: Tiền nhà | J36: =J14 -> 41799387
A37: 30 | H37: 2.7 | I37: Chi phí vận hành khác (điện, nước, internet, điện thoại, văn phòng phẩm …) | J37: =J15 -> 1093520
A38: 31 | H38: 2.8 | I38: Khoản vay | J38: =J16 -> 27000000
A39: 32 | H39: 2.9 | I39: BHXH | J39: =J17 -> 0
A40: 33 | H40: 2.11 | I40: Chi phí khác | J40: =J18 -> 0
...

Sheet T2
A1: I. Theo dõi khoản thu - chi (nhập mỗi ngày) | H1: II. Báo cáo kết quả hoạt động kinh doanh (25 hàng tháng)
A2: KHOẢN THU - CHI THÁNG T2/2025 | H2: KHOẢN | I2: DIỄN GIẢI | J2: Số tiền
A3: STT | B3: Ngày | C3: Số tiền | E3: KHOẢN | F3: DIỄN GIẢI | H3: 1 | I3: Doanh thu | J3: =SUM(J4:J6) -> 83099693
C4: THU | D4: CHI | H4: 1.1 | I4: Doanh thu bán hàng | J4: =SUMIF($E$8:$E$54,1.1,$C$8:$C$45) -> 83099693
H5: 1.2 | I5: Khoản thu bán hàng khác | J5: =SUMIF($E$8:$E$54,1.2,$C$8:$C$45) -> 0
H6: 1.3 | I6: Các khoản giảm trừ DT (ưu đãi, …) | J6: =SUMIF($E$8:$E$54,1.3,$C$8:$C$45) -> 0
C7: =SUM(C8:C66) -> 83099693 | D7: =SUM(D8:D66) -> 142261299 | G7: Lọc
A8: 1 | B8: 45708 | D8: 4645000 | E8: 2,7 | F8: Phí vận hành vp T2.25 | H8: 2 | I8: Chi phí | J8: =SUM(J9:J19) -> 142261299
A9: 2 | B9: 45700 | D9: 26000000 | E9: 2,8 | F9: Thanh toán khoản vay oto | H9: 2.1 | I9: Giá vốn hàng bán | J9: =SUMIF($E$8:$E$54,2.1,$D$8:$D$45) -> 0
A10: 3 | B10: 45700 | D10: 10865096 | E10: 2,5 | F10: HH TP/QL Lavida | H10: 2.2 | I10: Chi phí Lương | J10: =SUMIF($E$8:$E$54,2.2,$D$8:$D$45) -> 49646061
A11: 4 | B11: 45695 | D11: 49646061 | E11: 2,2 | F11: lương T1.25 | H11: 2.3 | I11: Chi phí TT MKT | J11: =SUMIF($E$8:$E$54,2.3,$D$8:$D$45) -> 2500000
A12: 5 | B12: 45695 | D12: 1000000 | E12: 2,3 | F12: Nạp tiền bds.com | H12: 2.4 | I12: Chi phí tuyển dụng | J12: =SUMIF($E$8:$E$54,2.4,$D$8:$D$45) -> 0
A13: 6 | B13: 45699 | C13: 83099693 | E13: 1,1 | F13: THANH TOAN PHI MOI GIOI CAN B2.0606- DA LAVIDA+ ( HD 4 NGAY 22/01/25) | H13: 2.5 | I13: Chi phí vận hành bán hàng | J13: =SUMIF($E$8:$E$54,2.5,$D$8:$D$45) -> 39470238
A14: 7 | B14: 45700 | D14: 28605142 | E14: 2,5 | F14: TIEN HH DOT 2 LAVIDA+ B2.0606 THEO TB 53.2024.LHI.TB-120225 | H14: 2.6 | I14: Tiền nhà | J14: =SUMIF($E$8:$E$54,2.6,$D$8:$D$45) -> 20000000
A15: 8 | B15: 45702 | D15: 1500000 | E15: 2,3 | F15: Nạp tiền bds.com | H15: 2.7 | I15: Chi phí vận hành khác (điện, nước, internet, điện thoại, văn phòng phẩm …) | J15: =SUMIF($E$8:$E$54,2.7,$D$8:$D$45) -> 4645000
A16: 9 | B16: 45712 | D16: 20000000 | E16: 2,6 | F16: Thanh lý tiền vp 2.25 | H16: 2.8 | I16: Khoản vay | J16: =SUMIF($E$8:$E$54,2.8,$D$8:$D$45) -> 26000000
A17: 10 | H17: 2.9 | I17: BHXH | J17: =SUMIF($E$8:$E$54,2.9,$D$8:$D$45) -> 0
A18: 11 | H18: 2.11 | I18: Chi phí khác | J18: =SUMIF($E$8:$E$54,2.11,$D$8:$D$45) -> 0
A19: 12 | H19: 2.12 | I19: Khoảng chi bán hàng khác (hoàn tiền,đặt chỗ) | J19: =SUMIF($E$8:$E$54,2.12,$D$8:$D$45) -> 0
A20: 13 | H20: 3 | I20: Lợi nhuận (trước Thuế) | J20: =J3-J8 -> -59161606
A21: 14
A22: 15 | H22: III. Báo cáo lưu chuyển tiền tệ ( 25 hàng tháng )
A23: 16 | I23: DIỄN GIẢI | J23: Số tiền
A24: 17 | H24: A | I24: Số dư đầu kỳ (Tồn quỹ đầu kỳ) | J24: 0
A25: 18 | H25: B | I25: Phát sinh tăng trong kỳ | J25: =SUM(J26:J28) -> 83099693
A26: 19 | I26: Doanh thu bán hàng thực thu | J26: =J3 -> 83099693
A27: 20 | I27: Thu hồi công nợ
A28: 21 | I28: Đi vay
A29: 22 | H29: C | I29: Phát sinh giảm trong kỳ | J29: =SUM(J30:J41) -> 142261299
A30: 23 | H30: 2.1 | I30: Giá vốn hàng bán | J30: =J9 -> 0
A31: 24 | H31: 1.3 | I31: Khoảng chi bán hàng chiết khấu , ưu đãi
A32: 25 | H32: 2.2 | I32: Chi phí Lương | J32: =J10 -> 49646061
A33: 26 | H33: 2.3 | I33: Chi phí TT MKT | J33: =J11 -> 2500000
A34: 27 | H34: 2.4 | I34: Chi phí tuyển dụng | J34: =J12 -> 0
A35: 28 | H35: 2.5 | I35: Chi phí vận hành bán hàng | J35: =J13 -> 39470238
A36: 29 | H36: 2.6 | I36: Tiền nhà | J36: =J14 -> 20000000
A37: 30 | H37: 2.7 | I37: Chi phí vận hành khác (điện, nước, internet, điện thoại, văn phòng phẩm …) | J37: =J15 -> 4645000
A38: 31 | H38: 2.8 | I38: Khoản vay | J38: =J16 -> 26000000
A39: 32 | H39: 2.9 | I39: BHXH | J39: =J17 -> 0
A40: 33 | H40: 2.11 | I40: Chi phí khác | J40: =J18 -> 0
...

Sheet T3
A1: I. Theo dõi khoản thu - chi (nhập mỗi ngày) | H1: II. Báo cáo kết quả hoạt động kinh doanh (25 hàng tháng)
A2: KHOẢN THU - CHI THÁNG T3/2025 | H2: KHOẢN | I2: DIỄN GIẢI | J2: Số tiền
A3: STT | B3: Ngày | C3: Số tiền | E3: KHOẢN | F3: DIỄN GIẢI | H3: 1 | I3: Doanh thu | J3: =SUM(J4:J6) -> 490340000
C4: THU | D4: CHI | H4: 1.1 | I4: Doanh thu bán hàng | J4: =SUMIF($E$8:$E$54,1.1,$C$8:$C$45) -> 0
H5: 1.2 | I5: Khoản thu bán hàng khác | J5: =SUMIF($E$8:$E$54,1.2,$C$8:$C$45) -> 490340000
H6: 1.3 | I6: Các khoản giảm trừ DT (ưu đãi, …) | J6: =SUMIF($E$8:$E$54,1.3,$C$8:$C$45) -> 0
C7: =SUM(C8:C100) -> 490340000 | D7: =SUM(D8:D100) -> 96449060 | G7: Lọc
A8: 1 | B8: 45723 | D8: 1276000 | E8: 2,11 | F8: Gia hạn chữ ký số | H8: 2 | I8: Chi phí | J8: =SUM(J9:J19) -> 96449060
A9: 2 | B9: 45719 | D9: 200000 | E9: 2,11 | F9: Chuyển tiền hỗ trợ thanh lý bàn ghế | H9: 2.1 | I9: Giá vốn hàng bán | J9: =SUMIF($E$8:$E$54,2.1,$D$8:$D$45) -> 0
A10: 3 | B10: 45719 | D10: 300000 | E10: 2,11 | F10: Chuyển tiền hỗ trợ sơn tường tòa nhà 655 | H10: 2.2 | I10: Chi phí Lương | J10: =SUMIF($E$8:$E$54,2.2,$D$8:$D$45) -> 49823342
A11: 4 | B11: 45719 | D11: 700000 | E11: 2,11 | F11: Chuyển tiền hỗ trợ gỡ bảng hiệu tòa nhà 656 | H11: 2.3 | I11: Chi phí TT MKT | J11: =SUMIF($E$8:$E$54,2.3,$D$8:$D$45) -> 800000
A12: 5 | B12: 45719 | C12: 5340000 | E12: 1,2 | F12: Thanh lý bàn ghế văn phòng | H12: 2.4 | I12: Chi phí tuyển dụng | J12: =SUMIF($E$8:$E$54,2.4,$D$8:$D$45) -> 0
A13: 6 | B13: 45727 | D13: 8900000 | E13: 2,9 | F13: Thanh toán BHXH T1-2.25 | H13: 2.5 | I13: Chi phí vận hành bán hàng | J13: =SUMIF($E$8:$E$54,2.5,$D$8:$D$45) -> 0
A14: 7 | B14: 45727 | D14: 4213718 | E14: 2,11 | F14: Nộp thuế môn bài, thuế quý 4.24 | H14: 2.6 | I14: Tiền nhà | J14: =SUMIF($E$8:$E$54,2.6,$D$8:$D$45) -> 0
A15: 8 | B15: 45727 | D15: 49823342 | E15: 2,2 | F15: Lương tháng 2.25 | H15: 2.7 | I15: Chi phí vận hành khác (điện, nước, internet, điện thoại, văn phòng phẩm …) | J15: =SUMIF($E$8:$E$54,2.7,$D$8:$D$45) -> 0
A16: 9 | B16: 45731 | D16: 200000 | E16: 2,3 | F16: Nộp tiền BDS.com | H16: 2.8 | I16: Khoản vay | J16: =SUMIF($E$8:$E$54,2.8,$D$8:$D$45) -> 26000000
A17: 10 | B17: 45737 | D17: 300000 | E17: 2,3 | F17: Nộp tiền BDS.com | H17: 2.9 | I17: BHXH | J17: =SUMIF($E$8:$E$54,2.9,$D$8:$D$45) -> 8900000
A18: 11 | B18: 45740 | D18: 300000 | E18: 2,3 | F18: Nộp tiền BDS.com | H18: 2.11 | I18: Chi phí khác | J18: =SUMIF($E$8:$E$54,2.11,$D$8:$D$45) -> 10925718
A19: 12 | B19: 45727 | C19: 200000000 | E19: 1,2 | F19: CONG TY TNHH O TO HOANG ANNA MUA XE 51D66546 | H19: 2.12 | I19: Khoảng chi bán hàng khác (hoàn tiền,đặt chỗ) | J19: =SUMIF($E$8:$E$54,2.12,$D$8:$D$45) -> 0
A20: 13 | B20: 45727 | C20: =485000000-C19 -> 285000000 | E20: 1,2 | F20: CONG TY TNHH O TO HOANG ANNA MUA XE 51D66546 (Cá nhân) | H20: 3 | I20: Lợi nhuận (trước Thuế) | J20: =J3-J8 -> 393890940
A21: 14 | B21: 45727 | D21: 2000000 | E21: 2,11 | F21: Đóng thuế môn bài
A22: 15 | B22: 45727 | D22: 2171000 | E22: 2,11 | F22: Đóng thuế (phạt nộp chậm) | H22: III. Báo cáo lưu chuyển tiền tệ ( 25 hàng tháng )
A23: 16 | B23: 45727 | D23: 20000 | E23: 2,11 | F23: Nộp thuế | I23: DIỄN GIẢI | J23: Số tiền
A24: 17 | B24: 45727 | D24: 45000 | E24: 2,11 | F24: Phí giao dịch nộp thuế | H24: A | I24: Số dư đầu kỳ (Tồn quỹ đầu kỳ) | J24: 0
A25: 18 | B25: 45721 | D25: 26000000 | E25: 2,8 | F25: Thanh toán khoản vay oto | H25: B | I25: Phát sinh tăng trong kỳ | J25: =SUM(J26:J28) -> 490340000
A26: 19 | I26: Doanh thu bán hàng thực thu | J26: =J3 -> 490340000
A27: 20 | I27: Thu hồi công nợ
A28: 21 | I28: Đi vay
A29: 22 | H29: C | I29: Phát sinh giảm trong kỳ | J29: =SUM(J30:J41) -> 96449060
A30: 23 | H30: 2.1 | I30: Giá vốn hàng bán | J30: =J9 -> 0
A31: 24 | H31: 1.3 | I31: Khoảng chi bán hàng chiết khấu , ưu đãi
A32: 25 | H32: 2.2 | I32: Chi phí Lương | J32: =J10 -> 49823342
A33: 26 | H33: 2.3 | I33: Chi phí TT MKT | J33: =J11 -> 800000
A34: 27 | H34: 2.4 | I34: Chi phí tuyển dụng | J34: =J12 -> 0
A35: 28 | H35: 2.5 | I35: Chi phí vận hành bán hàng | J35: =J13 -> 0
A36: 29 | H36: 2.6 | I36: Tiền nhà | J36: =J14 -> 0
A37: 30 | H37: 2.7 | I37: Chi phí vận hành khác (điện, nước, internet, điện thoại, văn phòng phẩm …) | J37: =J15 -> 0
A38: 31 | H38: 2.8 | I38: Khoản vay | J38: =J16 -> 26000000
A39: 32 | H39: 2.9 | I39: BHXH | J39: =J17 -> 8900000
A40: 33 | H40: 2.11 | I40: Chi phí khác | J40: =J18 -> 10925718
...

Sheet T4
A1: I. Theo dõi khoản thu - chi (nhập mỗi ngày) | H1: II. Báo cáo kết quả hoạt động kinh doanh (25 hàng tháng)
A2: KHOẢN THU - CHI THÁNG T4/2025 | H2: KHOẢN | I2: DIỄN GIẢI | J2: Số tiền
A3: STT | B3: Ngày | C3: Số tiền | E3: KHOẢN | F3: DIỄN GIẢI | H3: 1 | I3: Doanh thu | J3: =SUM(J4:J6) -> 0
C4: THU | D4: CHI | H4: 1.1 | I4: Doanh thu bán hàng | J4: =SUMIF($E$8:$E$54,1.1,$C$8:$C$45) -> 0
H5: 1.2 | I5: Khoản thu bán hàng khác | J5: =SUMIF($E$8:$E$54,1.2,$C$8:$C$45) -> 0
H6: 1.3 | I6: Các khoản giảm trừ DT (ưu đãi, …) | J6: =SUMIF($E$8:$E$54,1.3,$C$8:$C$45) -> 0
C7: =SUM(C8:C100) -> 0 | D7: =SUM(D8:D100) -> 77759355 | G7: Lọc
A8: 1 | B8: 45764 | D8: 3279000 | E8: 2,7 | F8: Màn hình máy tính MKT | H8: 2 | I8: Chi phí | J8: =SUM(J9:J19) -> 77759355
A9: 2 | B9: 45748 | D9: 1468000 | E9: 2,7 | F9: Chi phí vận hành văn phòng | H9: 2.1 | I9: Giá vốn hàng bán | J9: =SUMIF($E$8:$E$54,2.1,$D$8:$D$45) -> 0
A10: 3 | B10: 45751 | D10: 53002355 | E10: 2,2 | F10: Lương tháng 3 | H10: 2.2 | I10: Chi phí Lương | J10: =SUMIF($E$8:$E$54,2.2,$D$8:$D$45) -> 53002355
A11: 4 | B11: 45751 | D11: 13900000 | E11: 2,8 | F11: Vay oto 7 chỗ VIB | H11: 2.3 | I11: Chi phí TT MKT | J11: =SUMIF($E$8:$E$54,2.3,$D$8:$D$45) -> 0
A12: 5 | B12: 45756 | D12: 710000 | E12: 2,5 | F12: Phí xe di chuyển dự án BD | H12: 2.4 | I12: Chi phí tuyển dụng | J12: =SUMIF($E$8:$E$54,2.4,$D$8:$D$45) -> 0
A13: 6 | B13: 45758 | D13: 5400000 | E13: 2,7 | F13: Thanh toán Lark Đợt 2 | H13: 2.5 | I13: Chi phí vận hành bán hàng | J13: =SUMIF($E$8:$E$54,2.5,$D$8:$D$45) -> 710000
A14: 7 | H14: 2.6 | I14: Tiền nhà | J14: =SUMIF($E$8:$E$54,2.6,$D$8:$D$45) -> 0
A15: 8 | H15: 2.7 | I15: Chi phí vận hành khác (điện, nước, internet, điện thoại, văn phòng phẩm …) | J15: =SUMIF($E$8:$E$54,2.7,$D$8:$D$45) -> 10147000
A16: 9 | H16: 2.8 | I16: Khoản vay | J16: =SUMIF($E$8:$E$54,2.8,$D$8:$D$45) -> 13900000
A17: 10 | H17: 2.9 | I17: BHXH | J17: =SUMIF($E$8:$E$54,2.9,$D$8:$D$45) -> 0
A18: 11 | H18: 2.11 | I18: Chi phí khác | J18: =SUMIF($E$8:$E$54,2.11,$D$8:$D$45) -> 0
A19: 12 | H19: 2.12 | I19: Khoảng chi bán hàng khác (hoàn tiền,đặt chỗ) | J19: =SUMIF($E$8:$E$54,2.12,$D$8:$D$45) -> 0
A20: 13 | H20: 3 | I20: Lợi nhuận (trước Thuế) | J20: =J3-J8 -> -77759355
A21: 14
A22: 15 | H22: III. Báo cáo lưu chuyển tiền tệ ( 25 hàng tháng )
A23: 16 | I23: DIỄN GIẢI | J23: Số tiền
A24: 17 | H24: A | I24: Số dư đầu kỳ (Tồn quỹ đầu kỳ) | J24: 0
A25: 18 | H25: B | I25: Phát sinh tăng trong kỳ | J25: =SUM(J26:J28) -> 0
A26: 19 | I26: Doanh thu bán hàng thực thu | J26: =J3 -> 0
A27: 20 | I27: Thu hồi công nợ
A28: 21 | I28: Đi vay
A29: 22 | H29: C | I29: Phát sinh giảm trong kỳ | J29: =SUM(J30:J41) -> 77759355
A30: 23 | H30: 2.1 | I30: Giá vốn hàng bán | J30: =J9 -> 0
A31: 24 | H31: 1.3 | I31: Khoảng chi bán hàng chiết khấu , ưu đãi
A32: 25 | H32: 2.2 | I32: Chi phí Lương | J32: =J10 -> 53002355
A33: 26 | H33: 2.3 | I33: Chi phí TT MKT | J33: =J11 -> 0
A34: 27 | H34: 2.4 | I34: Chi phí tuyển dụng | J34: =J12 -> 0
A35: 28 | H35: 2.5 | I35: Chi phí vận hành bán hàng | J35: =J13 -> 710000
A36: 29 | H36: 2.6 | I36: Tiền nhà | J36: =J14 -> 0
A37: 30 | H37: 2.7 | I37: Chi phí vận hành khác (điện, nước, internet, điện thoại, văn phòng phẩm …) | J37: =J15 -> 10147000
A38: 31 | H38: 2.8 | I38: Khoản vay | J38: =J16 -> 13900000
A39: 32 | H39: 2.9 | I39: BHXH | J39: =J17 -> 0
A40: 33 | H40: 2.11 | I40: Chi phí khác | J40: =J18 -> 0
...

Sheet T5
A1: I. Theo dõi khoản thu - chi (nhập mỗi ngày) | H1: II. Báo cáo kết quả hoạt động kinh doanh (25 hàng tháng)
A2: KHOẢN THU - CHI THÁNG T5/2025 | H2: KHOẢN | I2: DIỄN GIẢI | J2: Số tiền
A3: STT | B3: Ngày | C3: Số tiền | E3: KHOẢN | F3: DIỄN GIẢI | H3: 1 | I3: Doanh thu | J3: =SUM(J4:J6) -> 0
C4: THU | D4: CHI | H4: 1.1 | I4: Doanh thu bán hàng | J4: =SUMIF($E$8:$E$54,1.1,$C$8:$C$45) -> 0
H5: 1.2 | I5: Khoản thu bán hàng khác | J5: =SUMIF($E$8:$E$54,1.2,$C$8:$C$45) -> 0
H6: 1.3 | I6: Các khoản giảm trừ DT (ưu đãi, …) | J6: =SUMIF($E$8:$E$54,1.3,$C$8:$C$45) -> 0
C7: =SUM(C8:C100) -> 0 | D7: =SUM(D8:D100) -> 96031632 | G7: Lọc
A8: 1 | B8: 45806 | D8: 2646000 | E8: 2,7 | F8: Chi phí vận hành văn phòng | H8: 2 | I8: Chi phí | J8: =SUM(J9:J19) -> 96031632
A9: 2 | B9: 45779 | D9: 63076632 | E9: 2,2 | F9: Lương tháng 4 | H9: 2.1 | I9: Giá vốn hàng bán | J9: =SUMIF($E$8:$E$54,2.1,$D$8:$D$45) -> 0
A10: 3 | B10: 45787 | D10: 4000000 | E10: 2,6 | F10: Cọc văn phòng 227A | H10: 2.2 | I10: Chi phí Lương | J10: =SUMIF($E$8:$E$54,2.2,$D$8:$D$45) -> 63076632
A11: 4 | B11: 45789 | D11: 10000000 | E11: 2,6 | F11: Cọc văn phòng 227A | H11: 2.3 | I11: Chi phí TT MKT | J11: =SUMIF($E$8:$E$54,2.3,$D$8:$D$45) -> 0
A12: 5 | B12: 45800 | D12: 2709000 | E12: 2,6 | F12: Tiền thuê vp tháng 5 | H12: 2.4 | I12: Chi phí tuyển dụng | J12: =SUMIF($E$8:$E$54,2.4,$D$8:$D$45) -> 0
A13: 6 | B13: 45782 | D13: 13600000 | E13: 2,8 | F13: Vay oto 7 chỗ VIB | H13: 2.5 | I13: Chi phí vận hành bán hàng | J13: =SUMIF($E$8:$E$54,2.5,$D$8:$D$45) -> 0
A14: 7 | H14: 2.6 | I14: Tiền nhà | J14: =SUMIF($E$8:$E$54,2.6,$D$8:$D$45) -> 16709000
A15: 8 | H15: 2.7 | I15: Chi phí vận hành khác (điện, nước, internet, điện thoại, văn phòng phẩm …) | J15: =SUMIF($E$8:$E$54,2.7,$D$8:$D$45) -> 2646000
A16: 9 | H16: 2.8 | I16: Khoản vay | J16: =SUMIF($E$8:$E$54,2.8,$D$8:$D$45) -> 13600000
A17: 10 | H17: 2.9 | I17: BHXH | J17: =SUMIF($E$8:$E$54,2.9,$D$8:$D$45) -> 0
A18: 11 | H18: 2.11 | I18: Chi phí khác | J18: =SUMIF($E$8:$E$54,2.11,$D$8:$D$45) -> 0
A19: 12 | H19: 2.12 | I19: Khoảng chi bán hàng khác (hoàn tiền,đặt chỗ) | J19: =SUMIF($E$8:$E$54,2.12,$D$8:$D$45) -> 0
A20: 13 | H20: 3 | I20: Lợi nhuận (trước Thuế) | J20: =J3-J8 -> -96031632
A21: 14
A22: 15 | H22: III. Báo cáo lưu chuyển tiền tệ ( 25 hàng tháng )
A23: 16 | I23: DIỄN GIẢI | J23: Số tiền
A24: 17 | H24: A | I24: Số dư đầu kỳ (Tồn quỹ đầu kỳ) | J24: 0
A25: 18 | H25: B | I25: Phát sinh tăng trong kỳ | J25: =SUM(J26:J28) -> 0
A26: 19 | I26: Doanh thu bán hàng thực thu | J26: =J3 -> 0
A27: 20 | I27: Thu hồi công nợ
A28: 21 | I28: Đi vay
A29: 22 | H29: C | I29: Phát sinh giảm trong kỳ | J29: =SUM(J30:J41) -> 96031632
A30: 23 | H30: 2.1 | I30: Giá vốn hàng bán | J30: =J9 -> 0
A31: 24 | H31: 1.3 | I31: Khoảng chi bán hàng chiết khấu , ưu đãi
A32: 25 | H32: 2.2 | I32: Chi phí Lương | J32: =J10 -> 63076632
A33: 26 | H33: 2.3 | I33: Chi phí TT MKT | J33: =J11 -> 0
A34: 27 | H34: 2.4 | I34: Chi phí tuyển dụng | J34: =J12 -> 0
A35: 28 | H35: 2.5 | I35: Chi phí vận hành bán hàng | J35: =J13 -> 0
A36: 29 | H36: 2.6 | I36: Tiền nhà | J36: =J14 -> 16709000
A37: 30 | H37: 2.7 | I37: Chi phí vận hành khác (điện, nước, internet, điện thoại, văn phòng phẩm …) | J37: =J15 -> 2646000
A38: 31 | H38: 2.8 | I38: Khoản vay | J38: =J16 -> 13600000
A39: 32 | H39: 2.9 | I39: BHXH | J39: =J17 -> 0
A40: 33 | H40: 2.11 | I40: Chi phí khác | J40: =J18 -> 0
...

Sheet T6
A1: I. Theo dõi khoản thu - chi (nhập mỗi ngày) | H1: II. Báo cáo kết quả hoạt động kinh doanh (25 hàng tháng)
A2: KHOẢN THU - CHI THÁNG T6/2025 | H2: KHOẢN | I2: DIỄN GIẢI | J2: Số tiền
A3: STT | B3: Ngày | C3: Số tiền | E3: KHOẢN | F3: DIỄN GIẢI | H3: 1 | I3: Doanh thu | J3: =SUM(J4:J6) -> 30000000
C4: THU | D4: CHI | H4: 1.1 | I4: Doanh thu bán hàng | J4: =SUMIF($E$8:$E$54,1.1,$C$8:$C$45) -> 30000000
H5: 1.2 | I5: Khoản thu bán hàng khác | J5: =SUMIF($E$8:$E$54,1.2,$C$8:$C$45) -> 0
H6: 1.3 | I6: Các khoản giảm trừ DT (ưu đãi, …) | J6: =SUMIF($E$8:$E$54,1.3,$C$8:$C$45) -> 0
C7: =SUM(C8:C100) -> 30000000 | D7: =SUM(D8:D100) -> 147431580 | G7: Lọc
A8: 1 | B8: 45815 | D8: 13600000 | E8: 2,8 | F8: Vay oto 7 chỗ VIB | H8: 2 | I8: Chi phí | J8: =SUM(J9:J19) -> 147431580
A9: 2 | B9: 45824 | D9: 900000 | E9: 2.5 | F9: Tiền xe dịch vụ HCM - ĐN | H9: 2.1 | I9: Giá vốn hàng bán | J9: =SUMIF($E$8:$E$54,2.1,$D$8:$D$45) -> 0
A10: 3 | B10: 45813 | D10: 64095080 | E10: 2.2 | F10: Lương tháng 5 | H10: 2.2 | I10: Chi phí Lương | J10: =SUMIF($E$8:$E$54,2.2,$D$8:$D$45) -> 79095080
A11: 4 | B11: 45820 | D11: 15400000 | E11: 2.6 | F11: Tiền thuê VP tháng 6, điện tháng 5 | H11: 2.3 | I11: Chi phí TT MKT | J11: =SUMIF($E$8:$E$54,2.3,$D$8:$D$45) -> 22536500
A12: 5 | B12: 45825 | D12: 13500000 | E12: 2.5 | F12: Thưởng nóng Lavida B2.0605 | H12: 2.4 | I12: Chi phí tuyển dụng | J12: =SUMIF($E$8:$E$54,2.4,$D$8:$D$45) -> 0
A13: 6 | B13: 45825 | D13: 300000 | E13: 2.3 | F13: CK Giang | H13: 2.5 | I13: Chi phí vận hành bán hàng | J13: =SUMIF($E$8:$E$54,2.5,$D$8:$D$45) -> 15300000
A14: 7 | B14: 45814 | D14: 1500000 | E14: 2.7 | F14: Đăng ký đổi địa chỉ GPKD | H14: 2.6 | I14: Tiền nhà | J14: =SUMIF($E$8:$E$54,2.6,$D$8:$D$45) -> 15400000
A15: 8 | B15: 45825 | D15: 15000000 | E15: 2.2 | F15: Tạm ứng lương anh Kiên | H15: 2.7 | I15: Chi phí vận hành khác (điện, nước, internet, điện thoại, văn phòng phẩm …) | J15: =SUMIF($E$8:$E$54,2.7,$D$8:$D$45) -> 1500000
A16: 9 | B16: 45834 | D16: 900000 | E16: 2.5 | F16: Tiền xe dịch vụ HCM - ĐN | H16: 2.8 | I16: Khoản vay | J16: =SUMIF($E$8:$E$54,2.8,$D$8:$D$45) -> 13600000
A17: 10 | B17: 45831 | D17: 9945000 | E17: 2.3 | F17: Phí MKT ads | H17: 2.9 | I17: BHXH | J17: =SUMIF($E$8:$E$54,2.9,$D$8:$D$45) -> 0
A18: 11 | B18: 45833 | D18: 10000000 | E18: 2.3 | F18: Thuê dịch vụ MKT ngoài | H18: 2.11 | I18: Chi phí khác | J18: =SUMIF($E$8:$E$54,2.11,$D$8:$D$45) -> 0
A19: 12 | B19: 45833 | D19: 291500 | E19: 2.3 | F19: Phí MKT tiktok ads | H19: 2.12 | I19: Khoảng chi bán hàng khác (hoàn tiền,đặt chỗ) | J19: =SUMIF($E$8:$E$54,2.12,$D$8:$D$45) -> 0
A20: 13 | B20: 45833 | D20: 2000000 | E20: 2.3 | H20: 3 | I20: Lợi nhuận (trước Thuế) | J20: =J3-J8 -> -117431580
A21: 14 | B21: 45825 | C21: 30000000 | E21: 1.1 | F21: Tạm ứng phí môi giới DA Lavida+
A22: 15 | H22: III. Báo cáo lưu chuyển tiền tệ ( 25 hàng tháng )
A23: 16 | I23: DIỄN GIẢI | J23: Số tiền
A24: 17 | H24: A | I24: Số dư đầu kỳ (Tồn quỹ đầu kỳ) | J24: 0
A25: 18 | H25: B | I25: Phát sinh tăng trong kỳ | J25: =SUM(J26:J28) -> 30000000
A26: 19 | I26: Doanh thu bán hàng thực thu | J26: =J3 -> 30000000
A27: 20 | I27: Thu hồi công nợ
A28: 21 | I28: Đi vay
A29: 22 | H29: C | I29: Phát sinh giảm trong kỳ | J29: =SUM(J30:J41) -> 147431580
A30: 23 | H30: 2.1 | I30: Giá vốn hàng bán | J30: =J9 -> 0
A31: 24 | H31: 1.3 | I31: Khoảng chi bán hàng chiết khấu , ưu đãi
A32: 25 | H32: 2.2 | I32: Chi phí Lương | J32: =J10 -> 79095080
A33: 26 | H33: 2.3 | I33: Chi phí TT MKT | J33: =J11 -> 22536500
A34: 27 | H34: 2.4 | I34: Chi phí tuyển dụng | J34: =J12 -> 0
A35: 28 | H35: 2.5 | I35: Chi phí vận hành bán hàng | J35: =J13 -> 15300000
A36: 29 | H36: 2.6 | I36: Tiền nhà | J36: =J14 -> 15400000
A37: 30 | H37: 2.7 | I37: Chi phí vận hành khác (điện, nước, internet, điện thoại, văn phòng phẩm …) | J37: =J15 -> 1500000
A38: 31 | H38: 2.8 | I38: Khoản vay | J38: =J16 -> 13600000
A39: 32 | H39: 2.9 | I39: BHXH | J39: =J17 -> 0
A40: 33 | H40: 2.11 | I40: Chi phí khác | J40: =J18 -> 0
...

Sheet T7
A1: I. Theo dõi khoản thu - chi (nhập mỗi ngày) | H1: II. Báo cáo kết quả hoạt động kinh doanh (25 hàng tháng)
A2: KHOẢN THU - CHI THÁNG T7/2025 | H2: KHOẢN | I2: DIỄN GIẢI | J2: Số tiền
A3: STT | B3: Ngày | C3: Số tiền | E3: KHOẢN | F3: DIỄN GIẢI | H3: 1 | I3: Doanh thu | J3: =SUM(J4:J6) -> 418072941
C4: THU | D4: CHI | H4: 1.1 | I4: Doanh thu bán hàng | J4: =SUMIF($E$8:$E$53,1.1,$C$8:$C$44) -> 418072941
H5: 1.2 | I5: Khoản thu bán hàng khác | J5: =SUMIF($E$8:$E$53,1.2,$C$8:$C$44) -> 0
H6: 1.3 | I6: Các khoản giảm trừ DT (ưu đãi, …) | J6: =SUMIF($E$8:$E$53,1.3,$C$8:$C$44) -> 0
C7: =SUM(C8:C100) -> 418072941 | D7: =SUM(D8:D100) -> 222170084 | G7: Lọc
B8: 45840 | D8: 1200000 | E8: 2,3 | F8: Mua phần mềm MKT | H8: 2 | I8: Chi phí | J8: =SUM(J9:J19) -> 222170084
B9: 45840 | D9: 31138039 | E9: 2.5 | F9: Hoa hồng căn B2.0605 Phạm Lê Nhật Vy Đợt 1 | H9: 2.1 | I9: Giá vốn hàng bán | J9: =SUMIF($E$8:$E$53,2.1,$D$8:$D$44) -> 0
B10: 45840 | D10: 900000 | E10: 2.5 | F10: Hoa hồng admin căn B2.0605 Đợt 1 | H10: 2.2 | I10: Chi phí Lương | J10: =SUMIF($E$8:$E$53,2.2,$D$8:$D$44) -> 72898462
B11: 45839 | C11: 70035083 | E11: 1.1 | F11: Phí môi giới căn B2.0605 Đợt 1 | H11: 2.3 | I11: Chi phí TT MKT | J11: =SUMIF($E$8:$E$53,2.3,$D$8:$D$44) -> 2400000
B12: 45841 | D12: 3050000 | E12: 2.11 | F12: Mua đồ công sở | H12: 2.4 | I12: Chi phí tuyển dụng | J12: =SUMIF($E$8:$E$53,2.4,$D$8:$D$44) -> 0
B13: 45841 | D13: 1215000 | E13: 2.11 | F13: Mua đồ công sở | H13: 2.5 | I13: Chi phí vận hành bán hàng | J13: =SUMIF($E$8:$E$53,2.5,$D$8:$D$44) -> 64076078
B14: 45840 | D14: 1200000 | E14: 2.3 | F14: Mua phần mềm MKT | H14: 2.6 | I14: Tiền nhà | J14: =SUMIF($E$8:$E$53,2.6,$D$8:$D$44) -> 32188000
B15: 45843 | D15: 72898462 | E15: 2.2 | F15: Lương tháng 6 | H15: 2.7 | I15: Chi phí vận hành khác (điện, nước, internet, điện thoại, văn phòng phẩm …) | J15: =SUMIF($E$8:$E$53,2.7,$D$8:$D$44) -> 0
B16: 45844 | D16: 9297000 | E16: 2.8 | F16: Vay oto 7 chỗ VIB gốc | H16: 2.8 | I16: Khoản vay | J16: =SUMIF($E$8:$E$53,2.8,$D$8:$D$44) -> 13300000
B17: 45844 | D17: 4003000 | E17: 2.8 | F17: Vay oto 7 chỗ VIB lãi | H17: 2.9 | I17: BHXH | J17: =SUMIF($E$8:$E$53,2.9,$D$8:$D$44) -> 0
B18: 45847 | D18: 31138039 | E18: 2.5 | F18: Hoa hồng căn B2.0605 Phạm Lê Nhật Vy Đợt 2 | H18: 2.11 | I18: Chi phí khác | J18: =SUMIF($E$8:$E$53,2.11,$D$8:$D$44) -> 37307544
B19: 45847 | D19: 18188000 | E19: 2.6 | F19: Tiền thuê VP tháng 7, điện tháng 6 | H19: 2.12 | I19: Khoảng chi bán hàng khác (hoàn tiền,đặt chỗ) | J19: =SUMIF($E$8:$E$53,2.12,$D$8:$D$44) -> 0
B20: 45847 | D20: 900000 | E20: 2.5 | F20: Hoa hồng admin căn B2.0605 Đợt 2 | H20: 3 | I20: Lợi nhuận (trước Thuế) | J20: =J3-J8 -> 195902857
B21: 45866 | D21: 9603951 | E21: 2.11 | F21: Hoàn thuế nội bộ tạm trích 2023-2024 - Nguyễn Hữu Nam
B22: 45866 | D22: 3809472 | E22: 2.11 | F22: Hoàn thuế nội bộ tạm trích 2023-2024 - Nguyễn Thành Long | H22: III. Báo cáo lưu chuyển tiền tệ ( 25 hàng tháng )
B23: 45866 | D23: 600000 | E23: 2.11 | F23: Hoàn thuế nội bộ tạm trích 2023-2024 - Phạm Phương Phương | I23: DIỄN GIẢI | J23: Số tiền
B24: 45866 | D24: 600000 | E24: 2.11 | F24: Hoàn thuế nội bộ tạm trích 2023-2024 - Lê Nguyễn Anh Thư | H24: A | I24: Số dư đầu kỳ (Tồn quỹ đầu kỳ) | J24: 0
B25: 45840 | D25: 14000000 | E25: 2.6 | F25: Cọc 1 tháng thuê vp 227A XVNT | H25: B | I25: Phát sinh tăng trong kỳ | J25: =SUM(J26:J28) -> 418072941
B26: 45845 | C26: 89053082 | E26: 1.1 | F26: VAREAL THANH TOAN PHI MOI GIOI THANG 05.2025 GD1.2025 DU AN LAVIDA+ HOA DON SO 8 CHO CONG TY LONG HOANG | I26: Doanh thu bán hàng thực thu | J26: =J3 -> 418072941
B27: 45846 | C27: 120451628 | E27: 1.1 | F27: CONG TY CO PHAN DAU TU CONG NGHE BAT DONG SAN DATA LOCA-GD 627249-2025-07-08T14:37:12-970407- /CTR/DATA LOCA THANH TOAN TIEN PHI DU AN FIATO AIRPORT THEO HOA DONSO 9/MAC/EAA4BC0000004C12 | I27: Thu hồi công nợ
B28: 45863 | C28: 108533148 | E28: 1.1 | F28: SGP TT PHI GIOI THIEU DA FIATO AIRPORT CITY, HOP DONG 04/2025/HDGTSP/SGP-LHI_HD 10 | I28: Đi vay
B29: 45863 | C29: 30000000 | E29: 1.1 | F29: CT CP DV BAT DONG SAN DANH KHOIGD 787362-2025-07-25T17:12:12- 970407-/CTR/CTY CP DV BDS DANH KHOI THANH LY TIEN DAT MUA DU AN FIATO | H29: C | I29: Phát sinh giảm trong kỳ | J29: =SUM(J30:J41) -> 222170084
B30: 45867 | D30: 16458121 | E30: 2.11 | F30: Nộp thuế | H30: 2.1 | I30: Giá vốn hàng bán | J30: =J9 -> 0
B31: 45867 | D31: 1971000 | E31: 2.11 | F31: Nộp thuế | H31: 1.3 | I31: Khoảng chi bán hàng chiết khấu , ưu đãi
H32: 2.2 | I32: Chi phí Lương | J32: =J10 -> 72898462
H33: 2.3 | I33: Chi phí TT MKT | J33: =J11 -> 2400000
H34: 2.4 | I34: Chi phí tuyển dụng | J34: =J12 -> 0
H35: 2.5 | I35: Chi phí vận hành bán hàng | J35: =J13 -> 64076078
H36: 2.6 | I36: Tiền nhà | J36: =J14 -> 32188000
H37: 2.7 | I37: Chi phí vận hành khác (điện, nước, internet, điện thoại, văn phòng phẩm …) | J37: =J15 -> 0
H38: 2.8 | I38: Khoản vay | J38: =J16 -> 13300000
H39: 2.9 | I39: BHXH | J39: =J17 -> 0
H40: 2.11 | I40: Chi phí khác | J40: =J18 -> 37307544
...

Sheet T8
A1: I. Theo dõi khoản thu - chi (nhập mỗi ngày) | H1: II. Báo cáo kết quả hoạt động kinh doanh (25 hàng tháng)
A2: KHOẢN THU - CHI THÁNG T8/2025 | H2: KHOẢN | I2: DIỄN GIẢI | J2: Số tiền
A3: STT | B3: Ngày | C3: Số tiền | E3: KHOẢN | F3: DIỄN GIẢI | H3: 1 | I3: Doanh thu | J3: =SUM(J4:J6) -> 69942464
C4: THU | D4: CHI | H4: 1.1 | I4: Doanh thu bán hàng | J4: =SUMIF($E$8:$E$54,1.1,$C$8:$C$45) -> 69942464
H5: 1.2 | I5: Khoản thu bán hàng khác | J5: =SUMIF($E$8:$E$54,1.2,$C$8:$C$45) -> 0
H6: 1.3 | I6: Các khoản giảm trừ DT (ưu đãi, …) | J6: =SUMIF($E$8:$E$54,1.3,$C$8:$C$45) -> 0
C7: =SUM(C8:C100) -> 69942464 | D7: =SUM(D8:D100) -> 408832810 | G7: Lọc
B8: 45874 | D8: 93072308 | E8: 2.2 | F8: Lương tháng 7 | H8: 2 | I8: Chi phí | J8: =SUM(J9:J19) -> 408832810
B9: 45874 | D9: 14000000 | E9: 2.6 | F9: Tiền thuê VP tháng 8 | H9: 2.1 | I9: Giá vốn hàng bán | J9: =SUMIF($E$8:$E$54,2.1,$D$8:$D$45) -> 0
B10: 45874 | D10: 1400000 | E10: 2.6 | F10: Tiền thuê VP tháng 8 VAT | H10: 2.2 | I10: Chi phí Lương | J10: =SUMIF($E$8:$E$54,2.2,$D$8:$D$45) -> 93072308
B11: 45874 | D11: 2388887 | E11: 2.6 | F11: Tiền điện tháng 7 | H11: 2.3 | I11: Chi phí TT MKT | J11: =SUMIF($E$8:$E$54,2.3,$D$8:$D$45) -> 4039200
B12: 45874 | D12: 191112 | E12: 2.6 | F12: Tiền điện tháng 7 VAT | H12: 2.4 | I12: Chi phí tuyển dụng | J12: =SUMIF($E$8:$E$54,2.4,$D$8:$D$45) -> 0
B13: 45874 | D13: 2789000 | E13: 2.7 | F13: Phí vận hành văn phòng | H13: 2.5 | I13: Chi phí vận hành bán hàng | J13: =SUMIF($E$8:$E$54,2.5,$D$8:$D$45) -> 245163925
B14: 45875 | D14: 9297000 | E14: 2.8 | F14: Vay oto 7 chỗ VIB gốc | H14: 2.6 | I14: Tiền nhà | J14: =SUMIF($E$8:$E$54,2.6,$D$8:$D$45) -> 17979999
B15: 45875 | D15: 4203000 | E15: 2.8 | F15: Vay oto 7 chỗ VIB lãi | H15: 2.7 | I15: Chi phí vận hành khác (điện, nước, internet, điện thoại, văn phòng phẩm …) | J15: =SUMIF($E$8:$E$54,2.7,$D$8:$D$45) -> 2789000
B16: 45875 | D16: 2288378 | E16: 2.11 | F16: Hoàn thuế nội bộ tạm trích T4- 5.2025- Hà Văn giang | H16: 2.8 | I16: Khoản vay | J16: =SUMIF($E$8:$E$54,2.8,$D$8:$D$45) -> 13500000
B17: 45877 | D17: 2000000 | E17: 2.5 | F17: Tiền xe dịch vụ HCM - BT | H17: 2.9 | I17: BHXH | J17: =SUMIF($E$8:$E$54,2.9,$D$8:$D$45) -> 0
B18: 45894 | D18: 990000 | E18: 2.5 | F18: Hoa hồng admin căn FA.06.09 Đợt 1 | H18: 2.11 | I18: Chi phí khác | J18: =SUMIF($E$8:$E$54,2.11,$D$8:$D$45) -> 2288378
B19: 45894 | D19: 25219149 | E19: 2.5 | F19: Hoa hồng căn FA.06.09 Phạm Lê Nhật Vy Đợt 1 | H19: 2.12 | I19: Khoảng chi bán hàng khác (hoàn tiền,đặt chỗ) | J19: =SUMIF($E$8:$E$54,2.12,$D$8:$D$45) -> 30000000
B20: 45897 | D20: 990000 | E20: 2.5 | F20: Hoa hồng admin căn FA.06.08 Đợt 1 - Sàn PKH | H20: 3 | I20: Lợi nhuận (trước Thuế) | J20: =J3-J8 -> -338890346
B21: 45897 | D21: 990000 | E21: 2.5 | F21: Hoa hồng admin căn FC.3B.14 Đợt 1 - Sàn PKH
B22: 45897 | D22: 990000 | E22: 2.5 | F22: Hoa hồng admin căn FB.05.01 Đợt 1 - Sàn PKH | H22: III. Báo cáo lưu chuyển tiền tệ ( 25 hàng tháng )
B23: 45897 | C23: 63584058 | E23: 1.1 | F23: Doanh thu từ CĐT FA.06.09 Đợt 1 | I23: DIỄN GIẢI | J23: Số tiền
B24: 45897 | C24: 6358406 | E24: 1.1 | F24: Doanh thu từ CĐT FA.06.09 Đợt 1 - VAT | H24: A | I24: Số dư đầu kỳ (Tồn quỹ đầu kỳ) | J24: 0
B25: 45890 | D25: 94121044 | E25: 2.5 | F25: Chi phí môi giới FB.05.01 Đợt 1 - Sàn PKH | H25: B | I25: Phát sinh tăng trong kỳ | J25: =SUM(J26:J28) -> 69942464
B26: 45890 | D26: 9412104 | E26: 2.5 | F26: Chi phí môi giới FB.05.01 Đợt 1 - Sàn PKH VAT | I26: Doanh thu bán hàng thực thu | J26: =J3 -> 69942464
B27: 45888 | D27: 100410571 | E27: 2.5 | F27: Chi phí môi giới FA.06.08 & FC.3B.14 Đợt 1 - Sàn PKH | I27: Thu hồi công nợ
B28: 45888 | D28: 10041057 | E28: 2.5 | F28: Chi phí môi giới FA.06.08 & FC.3B.14 Đợt 1 - Sàn PKH VAT | I28: Đi vay
B29: 45898 | D29: 3740000 | E29: 2.3 | F29: Gói đăng tin TOP CV | H29: C | I29: Phát sinh giảm trong kỳ | J29: =SUM(J30:J41) -> 408832810
B30: 45898 | D30: 299200 | E30: 2.3 | F30: Gói đăng tin TOP CV VAT | H30: 2.1 | I30: Giá vốn hàng bán | J30: =J9 -> 0
B31: 45882 | D31: 30000000 | E31: 2.12 | F31: CTY TNHH LONG HOANG INVESTMENT HOAN DAT CHO KH WU SU JUNG DA FIATO AIRPORT CITY | H31: 1.3 | I31: Khoảng chi bán hàng chiết khấu , ưu đãi
H32: 2.2 | I32: Chi phí Lương | J32: =J10 -> 93072308
H33: 2.3 | I33: Chi phí TT MKT | J33: =J11 -> 4039200
H34: 2.4 | I34: Chi phí tuyển dụng | J34: =J12 -> 0
H35: 2.5 | I35: Chi phí vận hành bán hàng | J35: =J13 -> 245163925
H36: 2.6 | I36: Tiền nhà | J36: =J14 -> 17979999
H37: 2.7 | I37: Chi phí vận hành khác (điện, nước, internet, điện thoại, văn phòng phẩm …) | J37: =J15 -> 2789000
H38: 2.8 | I38: Khoản vay | J38: =J16 -> 13500000
H39: 2.9 | I39: BHXH | J39: =J17 -> 0
H40: 2.11 | I40: Chi phí khác | J40: =J18 -> 2288378
...

Sheet T9
A1: I. Theo dõi khoản thu - chi (nhập mỗi ngày) | H1: II. Báo cáo kết quả hoạt động kinh doanh (25 hàng tháng)
A2: KHOẢN THU - CHI THÁNG T9/2025 | H2: KHOẢN | I2: DIỄN GIẢI | J2: Số tiền
A3: STT | B3: Ngày | C3: Số tiền | E3: KHOẢN | F3: DIỄN GIẢI | H3: 1 | I3: Doanh thu | J3: =SUM(J4:J6) -> 100000000
C4: THU | D4: CHI | H4: 1.1 | I4: Doanh thu bán hàng | J4: =SUMIF($E$8:$E$54,1.1,$C$8:$C$45) -> 100000000
H5: 1.2 | I5: Khoản thu bán hàng khác | J5: =SUMIF($E$8:$E$54,1.2,$C$8:$C$45) -> 0
H6: 1.3 | I6: Các khoản giảm trừ DT (ưu đãi, …) | J6: =SUMIF($E$8:$E$54,1.3,$C$8:$C$45) -> 0
C7: =SUM(C8:C100) -> 100000000 | D7: =SUM(D8:D100) -> 231694626 | G7: Lọc
B8: 45905 | D8: 14000000 | E8: 2.6 | F8: Tiền thuê VP tháng 9 | H8: 2 | I8: Chi phí | J8: =SUM(J9:J19) -> 231694626
B9: 45905 | D9: 1400000 | E9: 2.6 | F9: Tiền thuê VP tháng 9 VAT | H9: 2.1 | I9: Giá vốn hàng bán | J9: =SUMIF($E$8:$E$54,2.1,$D$8:$D$45) -> 0
B10: 45905 | D10: 2240740 | E10: 2.6 | F10: Tiền điện tháng 8 | H10: 2.2 | I10: Chi phí Lương | J10: =SUMIF($E$8:$E$54,2.2,$D$8:$D$45) -> 86044626
B11: 45905 | D11: 179260 | E11: 2.6 | F11: Tiền điện tháng 8 VAT | H11: 2.3 | I11: Chi phí TT MKT | J11: =SUMIF($E$8:$E$54,2.3,$D$8:$D$45) -> 3000000
B12: 45905 | D12: 86044626 | E12: 2.2 | F12: Lương tháng 8 | H12: 2.4 | I12: Chi phí tuyển dụng | J12: =SUMIF($E$8:$E$54,2.4,$D$8:$D$45) -> 4000000
B13: 45909 | D13: 1000000 | E13: 2.3 | F13: Thuê diễn viên quay video | H13: 2.5 | I13: Chi phí vận hành bán hàng | J13: =SUMIF($E$8:$E$54,2.5,$D$8:$D$45) -> 0
B14: 45909 | D14: 2000000 | E14: 2.3 | F14: Thuê thiếp bị quay | H14: 2.6 | I14: Tiền nhà | J14: =SUMIF($E$8:$E$54,2.6,$D$8:$D$45) -> 17820000
B15: 45929 | D15: 2520000 | E15: 2.9 | F15: Chi BHXH tháng 7-9 của NV | H15: 2.7 | I15: Chi phí vận hành khác (điện, nước, internet, điện thoại, văn phòng phẩm …) | J15: =SUMIF($E$8:$E$54,2.7,$D$8:$D$45) -> 0
B16: 45929 | D16: 5160000 | E16: 2.9 | F16: Chi BHXH tháng 7-9 công ty | H16: 2.8 | I16: Khoản vay | J16: =SUMIF($E$8:$E$54,2.8,$D$8:$D$45) -> 13150000
B17: 45929 | D17: 4000000 | E17: 2.4 | F17: Tạm ứng phí tuyển dụng | H17: 2.9 | I17: BHXH | J17: =SUMIF($E$8:$E$54,2.9,$D$8:$D$45) -> 7680000
B18: 45924 | C18: 100000000 | E18: 1.1 | F18: Chuyen tien thanh toan dich vu theo hoa don so 12 ngay 24-09-2025-GD-243990- 240925 | H18: 2.11 | I18: Chi phí khác | J18: =SUMIF($E$8:$E$54,2.11,$D$8:$D$45) -> 100000000
B19: 45908 | D19: 13150000 | E19: 2.8 | F19: khoản vay oto T9.25 | H19: 2.12 | I19: Khoảng chi bán hàng khác (hoàn tiền,đặt chỗ) | J19: =SUMIF($E$8:$E$54,2.12,$D$8:$D$45) -> 0
B20: 45924 | D20: 100000000 | E20: 2.11 | F20: Rút tiền hoàn trả | H20: 3 | I20: Lợi nhuận (trước Thuế) | J20: =J3-J8 -> -131694626
H22: III. Báo cáo lưu chuyển tiền tệ ( 25 hàng tháng )
I23: DIỄN GIẢI | J23: Số tiền
H24: A | I24: Số dư đầu kỳ (Tồn quỹ đầu kỳ) | J24: 0
H25: B | I25: Phát sinh tăng trong kỳ | J25: =SUM(J26:J28) -> 100000000
I26: Doanh thu bán hàng thực thu | J26: =J3 -> 100000000
I27: Thu hồi công nợ
I28: Đi vay
H29: C | I29: Phát sinh giảm trong kỳ | J29: =SUM(J30:J41) -> 231694626
H30: 2.1 | I30: Giá vốn hàng bán | J30: =J9 -> 0
H31: 1.3 | I31: Khoảng chi bán hàng chiết khấu , ưu đãi
H32: 2.2 | I32: Chi phí Lương | J32: =J10 -> 86044626
H33: 2.3 | I33: Chi phí TT MKT | J33: =J11 -> 3000000
H34: 2.4 | I34: Chi phí tuyển dụng | J34: =J12 -> 4000000
H35: 2.5 | I35: Chi phí vận hành bán hàng | J35: =J13 -> 0
H36: 2.6 | I36: Tiền nhà | J36: =J14 -> 17820000
H37: 2.7 | I37: Chi phí vận hành khác (điện, nước, internet, điện thoại, văn phòng phẩm …) | J37: =J15 -> 0
H38: 2.8 | I38: Khoản vay | J38: =J16 -> 13150000
H39: 2.9 | I39: BHXH | J39: =J17 -> 7680000
H40: 2.11 | I40: Chi phí khác | J40: =J18 -> 100000000
H41: 2.12 | I41: Khoảng chi bán hàng khác (hoàn đặt chỗ) | J41: =J19 -> 0
...

Sheet T10
A1: I. Theo dõi khoản thu - chi (nhập mỗi ngày) | H1: II. Báo cáo kết quả hoạt động kinh doanh (25 hàng tháng)
A2: KHOẢN THU - CHI THÁNG T10/2025 | H2: KHOẢN | I2: DIỄN GIẢI | J2: Số tiền
A3: STT | B3: Ngày | C3: Số tiền | E3: KHOẢN | F3: DIỄN GIẢI | H3: 1 | I3: Doanh thu | J3: =SUM(J4:J6) -> 472747966
C4: THU | D4: CHI | H4: 1.1 | I4: Doanh thu bán hàng | J4: =SUMIF($E$8:$E$54,1.1,$C$8:$C$45) -> 0
H5: 1.2 | I5: Khoản thu bán hàng khác | J5: =SUMIF($E$8:$E$54,1.2,$C$8:$C$45) -> 472747966
H6: 1.3 | I6: Các khoản giảm trừ DT (ưu đãi, …) | J6: =SUMIF($E$8:$E$54,1.3,$C$8:$C$45) -> 0
C7: =SUM(C8:C100) -> 472747966 | D7: =SUM(D8:D100) -> 359524900 | G7: Lọc
B8: 45938 | D8: 16652000 | E8: 2,6 | F8: Phí thuê vp, điện tháng 10.25 | H8: 2 | I8: Chi phí | J8: =SUM(J9:J19) -> 359524900
B9: 45938 | D9: 13100000 | E9: 2,8 | F9: Khoản vay oto 7 chỗ T10.25 | H9: 2.1 | I9: Giá vốn hàng bán | J9: =SUMIF($E$8:$E$54,2.1,$D$8:$D$45) -> 0
B10: 45951 | D10: 1297000 | E10: 2,7 | F10: Chi phí vận hành văn phòng | H10: 2.2 | I10: Chi phí Lương | J10: =SUMIF($E$8:$E$54,2.2,$D$8:$D$45) -> 78763000
B11: 45952 | D11: 4212900 | E11: 2,4 | F11: Chi phí tuyển dụng | H11: 2.3 | I11: Chi phí TT MKT | J11: =SUMIF($E$8:$E$54,2.3,$D$8:$D$45) -> 245500000
B12: 45933 | D12: 66050000 | E12: 2,2 | F12: Lương tháng 9.25 Đợt 1 | H12: 2.4 | I12: Chi phí tuyển dụng | J12: =SUMIF($E$8:$E$54,2.4,$D$8:$D$45) -> 4212900
B13: 45954 | D13: 4713000 | E13: 2,2 | F13: Lương tháng 9.25 Đợt 2 | H13: 2.5 | I13: Chi phí vận hành bán hàng | J13: =SUMIF($E$8:$E$54,2.5,$D$8:$D$45) -> 0
B14: 45946 | D14: 1500000 | E14: 2,3 | F14: Làm video dự án A&T | H14: 2.6 | I14: Tiền nhà | J14: =SUMIF($E$8:$E$54,2.6,$D$8:$D$45) -> 16652000
B15: 45956 | D15: 10000000 | E15: 2,3 | F15: Thanh toán quảng cáo facebook | H15: 2.7 | I15: Chi phí vận hành khác (điện, nước, internet, điện thoại, văn phòng phẩm …) | J15: =SUMIF($E$8:$E$54,2.7,$D$8:$D$45) -> 1297000
B16: 45957 | D16: 20000000 | E16: 2,3 | F16: Thanh toán quảng cáo facebook | H16: 2.8 | I16: Khoản vay | J16: =SUMIF($E$8:$E$54,2.8,$D$8:$D$45) -> 13100000
B17: 45957 | D17: 8000000 | E17: 2,2 | F17: Tạm ứng lương Giang T10.25 | H17: 2.9 | I17: BHXH | J17: =SUMIF($E$8:$E$54,2.9,$D$8:$D$45) -> 0
B18: 45959 | D18: 800000 | E18: 2,3 | F18: Làm video | H18: 2.11 | I18: Chi phí khác | J18: =SUMIF($E$8:$E$54,2.11,$D$8:$D$45) -> 0
B19: 45960 | D19: 30000000 | E19: 2,3 | F19: Thanh toán quảng cáo facebook | H19: 2.12 | I19: Khoảng chi bán hàng khác (hoàn tiền,đặt chỗ) | J19: =SUMIF($E$8:$E$54,2.12,$D$8:$D$45) -> 0
B20: 45960 | D20: 200000 | E20: 2,3 | F20: Thanh toán quảng cáo facebook | H20: 3 | I20: Lợi nhuận (trước Thuế) | J20: =J3-J8 -> 113223066
B21: 45954 | C21: 82500000 | E21: 1,2 | F21: Phí dịch vụ MKT DA A&T Đợt 2
B22: 45954 | C22: 82500000 | E22: 1,2 | F22: Phí dịch vụ MKT DA Charm Đợt 2 | H22: III. Báo cáo lưu chuyển tiền tệ ( 25 hàng tháng )
B23: 45940 | C23: 82500000 | E23: 1,2 | F23: Phí dịch vụ MKT DA A&T Đợt 1 | I23: DIỄN GIẢI | J23: Số tiền
B24: 45943 | C24: 82500000 | E24: 1,2 | F24: Phí dịch vụ MKT DA Charm Đợt 1 | H24: A | I24: Số dư đầu kỳ (Tồn quỹ đầu kỳ) | J24: 0
B25: 45939 | C25: 120000000 | E25: 1,2 | F25: Phí dịch vụ MKT DA Gia Khải Đợt 1 | H25: B | I25: Phát sinh tăng trong kỳ | J25: =SUM(J26:J28) -> 472747966
B26: 45950 | C26: 2747966 | E26: 1,2 | F26: Phí dịch vụ MKT sàn PKH | I26: Doanh thu bán hàng thực thu | J26: =J3 -> 472747966
B27: 45948 | C27: 20000000 | E27: 1,2 | F27: Phí dịch vụ MKTchị Hường - Maison Grand | I27: Thu hồi công nợ
B28: 45938 | D28: 2000000 | E28: 2,3 | F28: Thanh toán quảng cáo facebook | I28: Đi vay
B29: 45939 | D29: 2000000 | E29: 2,3 | F29: Thanh toán quảng cáo facebook | H29: C | I29: Phát sinh giảm trong kỳ | J29: =SUM(J30:J41) -> 359524900
B30: 45939 | D30: 2000000 | E30: 2,3 | F30: Thanh toán quảng cáo facebook | H30: 2.1 | I30: Giá vốn hàng bán | J30: =J9 -> 0
B31: 45939 | D31: 2000000 | E31: 2,3 | F31: Thanh toán quảng cáo facebook | H31: 1.3 | I31: Khoảng chi bán hàng chiết khấu , ưu đãi
B32: 45940 | D32: 5000000 | E32: 2,3 | F32: Thanh toán quảng cáo facebook | H32: 2.2 | I32: Chi phí Lương | J32: =J10 -> 78763000
B33: 45943 | D33: 10000000 | E33: 2,3 | F33: Thanh toán quảng cáo facebook | H33: 2.3 | I33: Chi phí TT MKT | J33: =J11 -> 245500000
B34: 45944 | D34: 10000000 | E34: 2,3 | F34: Thanh toán quảng cáo facebook | H34: 2.4 | I34: Chi phí tuyển dụng | J34: =J12 -> 4212900
B35: 45948 | D35: 10000000 | E35: 2,3 | F35: Thanh toán quảng cáo facebook | H35: 2.5 | I35: Chi phí vận hành bán hàng | J35: =J13 -> 0
B36: 45950 | D36: 10000000 | E36: 2,3 | F36: Thanh toán quảng cáo facebook | H36: 2.6 | I36: Tiền nhà | J36: =J14 -> 16652000
B37: 45950 | D37: 10000000 | E37: 2,3 | F37: Thanh toán quảng cáo facebook | H37: 2.7 | I37: Chi phí vận hành khác (điện, nước, internet, điện thoại, văn phòng phẩm …) | J37: =J15 -> 1297000
B38: 45950 | D38: 10000000 | E38: 2,3 | F38: Thanh toán quảng cáo facebook | H38: 2.8 | I38: Khoản vay | J38: =J16 -> 13100000
B39: 45951 | D39: 10000000 | E39: 2,3 | F39: Thanh toán quảng cáo facebook | H39: 2.9 | I39: BHXH | J39: =J17 -> 0
B40: 45952 | D40: 10000000 | E40: 2,3 | F40: Thanh toán quảng cáo facebook | H40: 2.11 | I40: Chi phí khác | J40: =J18 -> 0
...

Sheet T11
A1: I. Theo dõi khoản thu - chi (nhập mỗi ngày) | H1: II. Báo cáo kết quả hoạt động kinh doanh (25 hàng tháng)
A2: KHOẢN THU - CHI THÁNG T11/2025 | H2: KHOẢN | I2: DIỄN GIẢI | J2: Số tiền
A3: STT | B3: Ngày | C3: Số tiền | E3: KHOẢN | F3: DIỄN GIẢI | H3: 1 | I3: Doanh thu | J3: =SUM(J4:J6) -> 158028579
C4: THU | D4: CHI | H4: 1.1 | I4: Doanh thu bán hàng | J4: =SUMIF($E$8:$E$41,1.1,$C$8:$C$41) -> 0
H5: 1.2 | I5: Khoản thu bán hàng khác | J5: =SUMIF($E$8:$E$41,1.2,$C$8:$C$41) -> 158028579 | L5: IV. Dự toán thu chi theo tuần:
H6: 1.3 | I6: Các khoản giảm trừ DT (ưu đãi, …) | J6: =SUMIF($E$8:$E$41,1.3,$C$8:$C$41) -> 0 | L6: Tuần | M6: Ngày dự kiến phát sinh | N6: Số tiền Khoản thu | O6: Số tiền Khoản chi | P6: Nội dung
B7: Tổng | C7: =SUM(C8:C41) -> 158028579 | D7: =SUM(D8:D41) -> 270052847 | H7: 2 | I7: Chi phí | J7: =SUM(J8:J18) -> 270052847 | L7: 1 (3-9/11/25) | M7: 45966 | O7: 50500000 | P7: Lương tháng 10.25
A8: 1 | B8: 45962 | D8: 20000000 | E8: 2,3 | F8: Thanh toán quảng cáo facebook | H8: 2.1 | I8: Giá vốn hàng bán | J8: =SUMIF($E$8:$E$41,2.1,$D$8:$D$41) -> 0 | M8: 45966 | O8: 5600000 | P8: BHXH T10.25
A9: 2 | B9: 45962 | D9: 15639464 | E9: 2,11 | F9: Sửa xe 7 chỗ | H9: 2.2 | I9: Chi phí Lương | J9: =SUMIF($E$8:$E$41,2.2,$D$8:$D$41) -> 56689383 | M9: 45966 | O9: 11124000 | P9: Phí thuê vp, điện tháng 11.25
A10: 3 | B10: 45966 | D10: 56689383 | E10: 2,2 | F10: Lương T10 | H10: 2.3 | I10: Chi phí TT MKT | J10: =SUMIF($E$8:$E$41,2.3,$D$8:$D$41) -> 172000000 | M10: 45966 | O10: 12800000 | P10: Khoản vay oto 7 chỗ T11.25
A11: 4 | B11: 45966 | D11: 11124000 | E11: 2,6 | F11: Thuê vp T11 | H11: 2.4 | I11: Chi phí tuyển dụng | J11: =SUMIF($E$8:$E$41,2.4,$D$8:$D$41) -> 0 | M11: 45969 | N11: 50000000 | P11: Phí dịch vụ MKT DA Gia Khải Đợt 2
A12: 5 | B12: 45966 | D12: 12800000 | E12: 2,8 | F12: Khoản vay oto T11 | H12: 2.5 | I12: Chi phí vận hành bán hàng | J12: =SUMIF($E$8:$E$41,2.5,$D$8:$D$41) -> 1800000 | M12: 45960 | N12: 110000000 | P12: Phí dịch vụ MKT DA A&T Đợt 3
A13: 6 | B13: 45967 | D13: 1800000 | E13: 2,5 | F13: Tiền xe dịch vụ HCM - BT | H13: 2.6 | I13: Tiền nhà | J13: =SUMIF($E$8:$E$41,2.6,$D$8:$D$41) -> 11124000 | M13: 45960 | N13: 110000000 | P13: Phí dịch vụ MKT DA Charm Đợt 3
A14: 7 | B14: 45985 | C14: 53028579 | E14: 1,2 | F14: Phí dịch vụ MKT chị Hường - The Emerald Garden View | H14: 2.7 | I14: Chi phí vận hành khác (điện, nước, internet, điện thoại, văn phòng phẩm …) | J14: =SUMIF($E$8:$E$41,2.7,$D$8:$D$41) -> 0 | L14: Tổng số tiền Thu/Chi trong tuần | N14: =SUM(N7:N13) -> 270000000 | O14: =SUM(O7:O13) -> 80024000
A15: 8 | B15: 45966 | C15: 50000000 | E15: 1,2 | F15: Phí dịch vụ MKT ĐPN - Aspira | H15: 2.8 | I15: Khoản vay | J15: =SUMIF($E$8:$E$41,2.8,$D$8:$D$41) -> 12800000 | L15: 2 (10-16/11/25) | M15: 45975 | O15: 5600000 | P15: BHXH T10.25
A16: 9 | B16: 45987 | C16: 55000000 | E16: 1,2 | F16: Phí dịch vụ MKT anh Duy - Aspira | H16: 2.9 | I16: BHXH | J16: =SUMIF($E$8:$E$41,2.9,$D$8:$D$41) -> 0 | M16: 45975 | O16: =50500000-10000000-30000000 -> 10500000 | P16: Lương tháng 10.25 Đợt 2
A17: 10 | B17: 45964 | D17: 20000000 | E17: 2,3 | F17: Thanh toán quảng cáo facebook | H17: 2.11 | I17: Chi phí khác | J17: =SUMIF($E$8:$E$41,2.11,$D$8:$D$41) -> 15639464 | M17: 45975 | N17: 110000000 | P17: Phí dịch vụ MKT DA A&T Đợt 3
A18: 11 | B18: 45967 | D18: 10000000 | E18: 2,3 | F18: Thanh toán quảng cáo facebook | H18: 2.12 | I18: Khoảng chi bán hàng khác (hoàn tiền,đặt chỗ) | J18: =SUMIF($E$8:$E$41,2.12,$D$8:$D$41) -> 0 | M18: 45975 | N18: 110000000 | P18: Phí dịch vụ MKT DA Charm Đợt 3
A19: 12 | B19: 45968 | D19: 10000000 | E19: 2,3 | F19: Thanh toán quảng cáo facebook | H19: 3 | I19: Lợi nhuận (trước Thuế) | J19: =J3-J7 -> -112024268 | L19: Tổng số tiền Thu/Chi trong tuần | N19: =SUM(N15:N18) -> 220000000 | O19: =SUM(O15:O18) -> 16100000
A20: 13 | B20: 45970 | D20: 2000000 | E20: 2,3 | F20: Thanh toán quảng cáo facebook | L20: 3 (17-23/11/25) | M20: 45982 | O20: 5600000 | P20: BHXH T10.25
A21: 14 | B21: 45971 | D21: 2000000 | E21: 2,3 | F21: Thanh toán quảng cáo facebook | H21: III. Báo cáo lưu chuyển tiền tệ ( 25 hàng tháng ) | M21: 45982 | N21: 110000000 | P21: Phí dịch vụ MKT DA Charm Đợt 3
A22: 15 | B22: 45971 | D22: 15000000 | E22: 2,3 | F22: Thanh toán quảng cáo facebook | I22: DIỄN GIẢI | J22: Số tiền | M22: 45982 | O22: =1000000+4700000 -> 5700000 | P22: Lương Tháng 10 Lần 2
A23: 16 | B23: 45973 | D23: 1000000 | E23: 2,3 | F23: Thanh toán quảng cáo facebook | H23: A | I23: Số dư đầu kỳ (Tồn quỹ đầu kỳ) | J23: 0 | L23: Tổng số tiền Thu/Chi trong tuần | N23: =SUM(N20:N22) -> 110000000 | O23: =SUM(O20:O22) -> 11300000
A24: 17 | B24: 45974 | D24: 500000 | E24: 2,3 | F24: Thanh toán quảng cáo facebook | H24: B | I24: Phát sinh tăng trong kỳ | J24: =SUM(J25:J27) -> 158028579 | L24: 4 (24-30/11/25) | M24: 45985 | O24: 79377022 | P24: Hoàn tiền DV FB GPT Land
A25: 18 | B25: 45974 | D25: 20000000 | E25: 2,3 | F25: Thanh toán quảng cáo facebook | I25: Doanh thu bán hàng thực thu | J25: =J3 -> 158028579 | M25: 45985 | O25: 5600000 | P25: BHXH T10.25
A26: 19 | B26: 45977 | D26: 10000000 | E26: 2,3 | F26: Thanh toán quảng cáo facebook | I26: Thu hồi công nợ | M26: 45985 | O26: 5600000 | P26: BHXH T11.25
A27: 20 | B27: 45978 | D27: 5000000 | E27: 2,3 | F27: Thanh toán quảng cáo facebook | I27: Đi vay | L27: Tổng số tiền Thu/Chi trong tuần | N27: =SUM(N24:N26) -> 0 | O27: =SUM(O24:O26) -> 90577022
A28: 21 | B28: 45980 | D28: 500000 | E28: 2,3 | F28: Thanh toán quảng cáo facebook | H28: C | I28: Phát sinh giảm trong kỳ | J28: =SUM(J29:J40) -> 270052847
A29: 22 | B29: 45980 | D29: 10000000 | E29: 2,3 | F29: Thanh toán quảng cáo facebook | H29: 2.1 | I29: Giá vốn hàng bán | J29: =J8 -> 0
A30: 23 | B30: 45982 | D30: 2000000 | E30: 2,3 | F30: Thanh toán quảng cáo facebook | H30: 1.3 | I30: Khoảng chi bán hàng chiết khấu , ưu đãi
A31: 24 | B31: 45983 | D31: 4000000 | E31: 2,3 | F31: Thanh toán quảng cáo facebook | H31: 2.2 | I31: Chi phí Lương | J31: =J9 -> 56689383
A32: 25 | B32: 45985 | D32: 20000000 | E32: 2,3 | F32: Thanh toán quảng cáo facebook | H32: 2.3 | I32: Chi phí TT MKT | J32: =J10 -> 172000000
A33: 26 | B33: 45987 | D33: 10000000 | E33: 2,3 | F33: Thanh toán quảng cáo facebook | H33: 2.4 | I33: Chi phí tuyển dụng | J33: =J11 -> 0
A34: 27 | B34: 45989 | D34: 10000000 | E34: 2,3 | F34: Thanh toán quảng cáo facebook | H34: 2.5 | I34: Chi phí vận hành bán hàng | J34: =J12 -> 1800000
H35: 2.6 | I35: Tiền nhà | J35: =J13 -> 11124000
H36: 2.7 | I36: Chi phí vận hành khác (điện, nước, internet, điện thoại, văn phòng phẩm …) | J36: =J14 -> 0
H37: 2.8 | I37: Khoản vay | J37: =J15 -> 12800000
H38: 2.9 | I38: BHXH | J38: =J16 -> 0
H39: 2.11 | I39: Chi phí khác | J39: =J17 -> 15639464
H40: 2.12 | I40: Khoảng chi bán hàng khác (hoàn đặt chỗ) | J40: =J18 -> 0
...

Sheet T12
A1: I. Theo dõi khoản thu - chi (nhập mỗi ngày) | H1: II. Báo cáo kết quả hoạt động kinh doanh (25 hàng tháng)
A2: KHOẢN THU - CHI THÁNG T12/2025 | H2: KHOẢN | I2: DIỄN GIẢI | J2: Số tiền
A3: STT | B3: Ngày | C3: Số tiền | E3: KHOẢN | F3: DIỄN GIẢI | H3: 1 | I3: Doanh thu | J3: =SUM(J4:J6) -> 295697978
C4: THU | D4: CHI | H4: 1.1 | I4: Doanh thu bán hàng | J4: =SUMIF($E$8:$E$100,1.1,$C$8:$C$100) -> 0
H5: 1.2 | I5: Khoản thu bán hàng khác | J5: =SUMIF($E$8:$E$100,1.2,$C$8:$C$100) -> 295697978 | L5: IV. Dự toán thu chi theo tuần:
H6: 1.3 | I6: Các khoản giảm trừ DT (ưu đãi, …) | J6: =SUMIF($E$8:$E$100,1.3,$C$8:$C$100) -> 0 | L6: Tuần | M6: Ngày dự kiến phát sinh | N6: Số tiền Khoản thu | O6: Số tiền Khoản chi | P6: Nội dung
B7: Tổng | C7: =SUM(C8:C100) -> 295697978 | D7: =SUM(D8:D100) -> 369183401 | H7: 2 | I7: Chi phí | J7: =SUM(J8:J18) -> 369183401 | L7: 2 (8-14/12/25) | M7: 45999 | O7: 45800000 | P7: Lương tháng 11.25
A8: 1 | B8: 45992 | D8: 7000000 | E8: 2,2 | F8: Tạm ứng phí dịch vụ Media - NV Giang T11 | H8: 2.1 | I8: Giá vốn hàng bán | J8: =SUMIF($E$8:$E$100,2.1,$D$8:$D$100) -> 0 | M8: 46001 | O8: 10756000 | P8: Phí thuê vp, điện tháng 12.25
A9: 2 | B9: 45995 | D9: 12600000 | E9: 2,8 | F9: Khoản vay oto T12.25 | H9: 2.2 | I9: Chi phí Lương | J9: =SUMIF($E$8:$E$100,2.2,$D$8:$D$100) -> 57416333 | M9: 45999 | O9: 12600000 | P9: Khoản vay oto 7 chỗ T12.25
A10: 3 | B10: 45995 | D10: 10756068 | E10: 2,6 | F10: Tiền thuê vp T12.25 | H10: 2.3 | I10: Chi phí TT MKT | J10: =SUMIF($E$8:$E$100,2.3,$D$8:$D$100) -> 268400000 | M10: 45999 | N10: 62700000 | P10: Phí dịch vụ MKT DA Sunshine
A11: 4 | B11: 45995 | D11: 45416333 | E11: 2,2 | F11: Lương tháng 12.25 | H11: 2.4 | I11: Chi phí tuyển dụng | J11: =SUMIF($E$8:$E$100,2.4,$D$8:$D$100) -> 0 | M11: 46001 | O11: =5600000*2 -> 11200000 | P11: BHXH T10-11.25
A12: 5 | B12: 46003 | D12: 2661000 | E12: 2,7 | F12: Phí vận hành công ty | H12: 2.5 | I12: Chi phí vận hành bán hàng | J12: =SUMIF($E$8:$E$100,2.5,$D$8:$D$100) -> 0 | M12: 46004 | N12: 150000000 | P12: Phí dịch vụ MKT Da Vin Cần Giờ
A13: 6 | B13: 46006 | D13: 1000000 | E13: 2,3 | F13: Phí thuê DV MKt - Nv San | H13: 2.6 | I13: Tiền nhà | J13: =SUMIF($E$8:$E$100,2.6,$D$8:$D$100) -> 10756068 | M13: 45999 | O13: 119422076 | P13: Ngân sách chạy ads Tuần 1
A14: 7 | B14: 46021 | D14: 17350000 | E14: 2,9 | F14: BHXH T10-12.25 | H14: 2.7 | I14: Chi phí vận hành khác (điện, nước, internet, điện thoại, văn phòng phẩm …) | J14: =SUMIF($E$8:$E$100,2.7,$D$8:$D$100) -> 2661000 | M14: 46004 | O14: 79377022 | P14: Hoàn tiền chạy ads GPTLand
A15: 8 | B15: 46022 | D15: 5000000 | E15: 2,2 | F15: Tạm ứng phí dịch vụ Media - NV Giang T12 | H15: 2.8 | I15: Khoản vay | J15: =SUMIF($E$8:$E$100,2.8,$D$8:$D$100) -> 12600000 | L15: Tổng số tiền Thu/Chi trong tuần | N15: =SUM(N7:N14) -> 212700000 | O15: =SUM(O7:O14) -> 279155098
A16: 9 | B16: 45992 | D16: 10000000 | E16: 2,3 | F16: Thanh toán quảng cáo facebook | H16: 2.9 | I16: BHXH | J16: =SUMIF($E$8:$E$100,2.9,$D$8:$D$100) -> 17350000 | L16: 3 (15-21/12/25) | M16: 46006 | O16: =5600000*3 -> 16800000 | P16: BHXH T10-11-12.25
A17: 10 | B17: 45994 | D17: 15000000 | E17: 2,3 | F17: Thanh toán quảng cáo facebook | H17: 2.11 | I17: Chi phí khác | J17: =SUMIF($E$8:$E$100,2.11,$D$8:$D$100) -> 0 | M17: 46006 | N17: 68750000 | P17: Phí dịch vụ MKT Da Ava Center
A18: 11 | B18: 45996 | D18: 5000000 | E18: 2,3 | F18: Thanh toán quảng cáo facebook | H18: 2.12 | I18: Khoảng chi bán hàng khác (hoàn tiền,đặt chỗ) | J18: =SUMIF($E$8:$E$100,2.12,$D$8:$D$100) -> 0 | M18: 46006 | O18: 1000000 | P18: Tiền CTV Chị San
A19: 12 | B19: 45997 | D19: 20000000 | E19: 2,3 | F19: Thanh toán quảng cáo facebook | H19: 3 | I19: Lợi nhuận (trước Thuế) | J19: =J3-J7 -> -73485423 | M19: 46006 | O19: 117755409 | P19: Ngân sách chạy ads Tuần 3
A20: 13 | B20: 45999 | D20: 20000000 | E20: 2,3 | F20: Thanh toán quảng cáo facebook | M20: 46006 | O20: 79377022 | P20: Hoàn tiền chạy ads GPTLand
A21: 14 | B21: 46001 | D21: 5000000 | E21: 2,3 | F21: Thanh toán quảng cáo facebook | M21: 46011 | N21: 57750000 | P21: Phí dịch vụ MKT Da T&T (Việt Á)
A22: 15 | B22: 46002 | D22: 8000000 | E22: 2,3 | F22: Thanh toán quảng cáo facebook | L22: Tổng số tiền Thu/Chi trong tuần | N22: =SUM(N16:N21) -> 126500000 | O22: =SUM(O16:O21) -> 214932431
A23: 16 | B23: 46003 | D23: 1500000 | E23: 2,3 | F23: Thanh toán quảng cáo facebook | H23: III. Báo cáo lưu chuyển tiền tệ ( 25 hàng tháng ) | L23: 4 (22-28/12/25)
A24: 17 | B24: 46003 | D24: 1000000 | E24: 2,3 | F24: Thanh toán quảng cáo facebook | I24: DIỄN GIẢI | J24: Số tiền
A25: 18 | B25: 46004 | D25: 10000000 | E25: 2,3 | F25: Thanh toán quảng cáo facebook | H25: A | I25: Số dư đầu kỳ (Tồn quỹ đầu kỳ) | J25: 0
A26: 19 | B26: 46004 | D26: 15000000 | E26: 2,3 | F26: Thanh toán quảng cáo facebook | H26: B | I26: Phát sinh tăng trong kỳ | J26: =SUM(J27:J29) -> 295697978 | L26: Tổng số tiền Thu/Chi trong tuần | N26: =SUM(N23:N25) -> 0 | O26: =SUM(O23:O25) -> 0
A27: 20 | B27: 46005 | D27: 7000000 | E27: 2,3 | F27: Thanh toán quảng cáo facebook | I27: Doanh thu bán hàng thực thu | J27: =J3 -> 295697978
A28: 21 | B28: 46005 | D28: 5000000 | E28: 2,3 | F28: Thanh toán quảng cáo facebook | I28: Thu hồi công nợ
A29: 22 | B29: 46006 | D29: 30000000 | E29: 2,3 | F29: Thanh toán quảng cáo facebook | I29: Đi vay
A30: 23 | B30: 46007 | D30: 10000000 | E30: 2,3 | F30: Thanh toán quảng cáo facebook | H30: C | I30: Phát sinh giảm trong kỳ | J30: =SUM(J31:J42) -> 369183401
A31: 24 | B31: 46009 | D31: 10000000 | E31: 2,3 | F31: Thanh toán quảng cáo facebook | H31: 2.1 | I31: Giá vốn hàng bán | J31: =J8 -> 0
A32: 25 | B32: 46010 | D32: 15000000 | E32: 2,3 | F32: Thanh toán quảng cáo facebook | H32: 1.3 | I32: Khoảng chi bán hàng chiết khấu , ưu đãi
A33: 26 | B33: 46013 | D33: 7900000 | E33: 2,3 | F33: Thanh toán quảng cáo facebook | H33: 2.2 | I33: Chi phí Lương | J33: =J9 -> 57416333
A34: 27 | B34: 46014 | D34: 2000000 | E34: 2,3 | F34: Thanh toán quảng cáo facebook | H34: 2.3 | I34: Chi phí TT MKT | J34: =J10 -> 268400000
A35: 28 | B35: 46014 | D35: 15000000 | E35: 2,3 | F35: Thanh toán quảng cáo facebook | H35: 2.4 | I35: Chi phí tuyển dụng | J35: =J11 -> 0
A36: 29 | B36: 46015 | D36: 8000000 | E36: 2,3 | F36: Thanh toán quảng cáo facebook | H36: 2.5 | I36: Chi phí vận hành bán hàng | J36: =J12 -> 0
A37: 30 | B37: 46016 | D37: 5000000 | E37: 2,3 | F37: Thanh toán quảng cáo facebook | H37: 2.6 | I37: Tiền nhà | J37: =J13 -> 10756068
A38: 31 | B38: 46017 | D38: 10000000 | E38: 2,3 | F38: Thanh toán quảng cáo facebook | H38: 2.7 | I38: Chi phí vận hành khác (điện, nước, internet, điện thoại, văn phòng phẩm …) | J38: =J14 -> 2661000
A39: 32 | B39: 46017 | D39: 2000000 | E39: 2,3 | F39: Thanh toán quảng cáo facebook | H39: 2.8 | I39: Khoản vay | J39: =J15 -> 12600000
A40: 33 | B40: 46017 | D40: 5000000 | E40: 2,3 | F40: Thanh toán quảng cáo facebook | H40: 2.9 | I40: BHXH | J40: =J16 -> 17350000
...

Sheet T1.26
A1: I. Theo dõi khoản thu - chi (nhập mỗi ngày) | H1: II. Báo cáo kết quả hoạt động kinh doanh (25 hàng tháng)
A2: KHOẢN THU - CHI THÁNG T1/2026 | H2: KHOẢN | I2: DIỄN GIẢI | J2: Số tiền
A3: STT | B3: Ngày | C3: Số tiền | E3: KHOẢN | F3: DIỄN GIẢI | H3: 1 | I3: Doanh thu | J3: =SUM(J4:J6) -> 0
C4: THU | D4: CHI | H4: 1.1 | I4: Doanh thu bán hàng | J4: =SUMIF($E$8:$E$47,1.1,$C$8:$C$47) -> 0
H5: 1.2 | I5: Khoản thu bán hàng khác | J5: =SUMIF($E$8:$E$47,1.2,$C$8:$C$47) -> 0 | L5: IV. Dự toán thu chi theo tuần:
H6: 1.3 | I6: Các khoản giảm trừ DT (ưu đãi, …) | J6: =SUMIF($E$8:$E$47,1.3,$C$8:$C$47) -> 0 | L6: Tuần | M6: Ngày dự kiến phát sinh | N6: Số tiền Khoản thu | O6: Số tiền Khoản chi | P6: Nội dung
B7: Tổng | C7: =SUM(C8:C47) -> 0 | D7: =SUM(D8:D47) -> 0 | H7: 2 | I7: Chi phí | J7: =SUM(J8:J19) -> 0 | L7: 1 (29/12 - 03/01/26 | M7: 46021 | O7: =5600000*3 -> 16800000 | P7: BHXH T10-12.25
A8: 1 | H8: 2.1 | I8: Giá vốn hàng bán | J8: =SUMIF($E$8:$E$47,2.1,$D$8:$D$47) -> 0 | M8: 46021 | N8: 57570000 | P8: Phí dịch vụ MKT Da T&T (Việt Á)
A9: 2 | H9: 2.2 | I9: Chi phí Lương | J9: =SUMIF($E$8:$E$47,2.2,$D$8:$D$47) -> 0 | M9: 46021 | N9: 15000000 | P9: Phí dịch vụ MKT Da Ava Center
A10: 3 | H10: 2.3 | I10: Chi phí TT MKT | J10: =SUMIF($E$8:$E$47,2.3,$D$8:$D$47) -> 0 | M10: 46021 | O10: 1833381 | P10: Hoàn ngân sách chạy Aspira (Duy Phạm)
A11: 4 | H11: 2.4 | I11: Chi phí tuyển dụng | J11: =SUMIF($E$8:$E$47,2.4,$D$8:$D$47) -> 0 | M11: 46021 | N11: 32628448 | P11: Phí dịch vụ MKT Da Aspira ĐPN (thanh toán thêm)
A12: 5 | H12: 2.5 | I12: Chi phí vận hành bán hàng | J12: =SUMIF($E$8:$E$47,2.5,$D$8:$D$47) -> 0 | M12: 46021 | N12: 4872122 | P12: Phí dịch vụ MKT Da Maison PKH (thanh toán thêm)
M13: 46020 | O13: 105750000 | P13: Ngân sách chạy ads Tuần 1
A14: 6 | H14: 2.6 | I14: Tiền nhà | J14: =SUMIF($E$8:$E$47,2.6,$D$8:$D$47) -> 0 | M14: 46022 | O14: 15998122 | P14: Hoàn ngân sách chạy Emerald (Chị Hường)
